[2024-11-10T15:19:31.010+0000] {local_task_job_runner.py:123} INFO - ::group::Pre task execution logs
[2024-11-10T15:19:31.042+0000] {taskinstance.py:2613} INFO - Dependencies all met for dep_context=non-requeueable deps ti=<TaskInstance: mongodb_atlas_fetch_load.load_and_validate manual__2024-11-10T15:19:14.620848+00:00 [queued]>
[2024-11-10T15:19:31.058+0000] {taskinstance.py:2613} INFO - Dependencies all met for dep_context=requeueable deps ti=<TaskInstance: mongodb_atlas_fetch_load.load_and_validate manual__2024-11-10T15:19:14.620848+00:00 [queued]>
[2024-11-10T15:19:31.059+0000] {taskinstance.py:2866} INFO - Starting attempt 1 of 1
[2024-11-10T15:19:31.086+0000] {taskinstance.py:2889} INFO - Executing <Task(PythonOperator): load_and_validate> on 2024-11-10 15:19:14.620848+00:00
[2024-11-10T15:19:31.101+0000] {warnings.py:112} WARNING - /home/***/.local/lib/python3.12/site-packages/***/task/task_runner/standard_task_runner.py:70: DeprecationWarning: This process (pid=718) is multi-threaded, use of fork() may lead to deadlocks in the child.
  pid = os.fork()

[2024-11-10T15:19:31.103+0000] {standard_task_runner.py:72} INFO - Started process 720 to run task
[2024-11-10T15:19:31.106+0000] {standard_task_runner.py:104} INFO - Running: ['***', 'tasks', 'run', 'mongodb_atlas_fetch_load', 'load_and_validate', 'manual__2024-11-10T15:19:14.620848+00:00', '--job-id', '143', '--raw', '--subdir', 'DAGS_FOLDER/et_pipeline.py', '--cfg-path', '/tmp/tmpztwugixp']
[2024-11-10T15:19:31.109+0000] {standard_task_runner.py:105} INFO - Job 143: Subtask load_and_validate
[2024-11-10T15:19:31.194+0000] {task_command.py:467} INFO - Running <TaskInstance: mongodb_atlas_fetch_load.load_and_validate manual__2024-11-10T15:19:14.620848+00:00 [running]> on host e9f90922e3c1
[2024-11-10T15:19:31.367+0000] {taskinstance.py:3132} INFO - Exporting env vars: AIRFLOW_CTX_DAG_OWNER='***' AIRFLOW_CTX_DAG_ID='mongodb_atlas_fetch_load' AIRFLOW_CTX_TASK_ID='load_and_validate' AIRFLOW_CTX_EXECUTION_DATE='2024-11-10T15:19:14.620848+00:00' AIRFLOW_CTX_TRY_NUMBER='1' AIRFLOW_CTX_DAG_RUN_ID='manual__2024-11-10T15:19:14.620848+00:00'
[2024-11-10T15:19:31.369+0000] {logging_mixin.py:190} INFO - Task instance is in running state
[2024-11-10T15:19:31.370+0000] {logging_mixin.py:190} INFO -  Previous state of the Task instance: queued
[2024-11-10T15:19:31.370+0000] {logging_mixin.py:190} INFO - Current task name:load_and_validate state:running start_date:2024-11-10 15:19:31.043182+00:00
[2024-11-10T15:19:31.371+0000] {logging_mixin.py:190} INFO - Dag name:mongodb_atlas_fetch_load and current dag run status:running
[2024-11-10T15:19:31.372+0000] {taskinstance.py:731} INFO - ::endgroup::
[2024-11-10T15:19:31.392+0000] {base.py:84} INFO - Retrieving connection 'mongo_default'
[2024-11-10T15:19:33.964+0000] {connection.py:277} WARNING - Connection schemes (type: google_cloud_platform) shall not contain '_' according to RFC3986.
[2024-11-10T15:19:33.966+0000] {base.py:84} INFO - Retrieving connection 'google_cloud_default'
[2024-11-10T15:19:35.541+0000] {gcs.py:594} INFO - File /tmp/mongo_data.json uploaded to raw_data/api_combined_data.json in ***_bucket_name bucket
[2024-11-10T15:19:35.543+0000] {hook.py:208} WARNING - Data lineage tracking is disabled. Register a hook lineage reader to start tracking hook lineage.
[2024-11-10T15:19:35.564+0000] {connection.py:277} WARNING - Connection schemes (type: google_cloud_platform) shall not contain '_' according to RFC3986.
[2024-11-10T15:19:35.566+0000] {base.py:84} INFO - Retrieving connection 'google_cloud_default'
[2024-11-10T15:19:35.699+0000] {hook.py:208} WARNING - Data lineage tracking is disabled. Register a hook lineage reader to start tracking hook lineage.
[2024-11-10T15:19:36.592+0000] {taskinstance.py:3311} ERROR - Task failed with exception
Traceback (most recent call last):
  File "/opt/airflow/dags/et_pipeline.py", line 55, in validate_data
    api_data = json.loads(data.decode("utf-8"))
               ^^^^^^^^^^^^^^^^^^^^^^^^^^^^^^^^
  File "/usr/local/lib/python3.12/json/__init__.py", line 346, in loads
    return _default_decoder.decode(s)
           ^^^^^^^^^^^^^^^^^^^^^^^^^^
  File "/usr/local/lib/python3.12/json/decoder.py", line 340, in decode
    raise JSONDecodeError("Extra data", s, end)
json.decoder.JSONDecodeError: Extra data: line 2 column 1 (char 2336)

During handling of the above exception, another exception occurred:

Traceback (most recent call last):
  File "/home/airflow/.local/lib/python3.12/site-packages/airflow/models/taskinstance.py", line 767, in _execute_task
    result = _execute_callable(context=context, **execute_callable_kwargs)
             ^^^^^^^^^^^^^^^^^^^^^^^^^^^^^^^^^^^^^^^^^^^^^^^^^^^^^^^^^^^^^
  File "/home/airflow/.local/lib/python3.12/site-packages/airflow/models/taskinstance.py", line 733, in _execute_callable
    return ExecutionCallableRunner(
           ^^^^^^^^^^^^^^^^^^^^^^^^
  File "/home/airflow/.local/lib/python3.12/site-packages/airflow/utils/operator_helpers.py", line 252, in run
    return self.func(*args, **kwargs)
           ^^^^^^^^^^^^^^^^^^^^^^^^^^
  File "/home/airflow/.local/lib/python3.12/site-packages/airflow/models/baseoperator.py", line 417, in wrapper
    return func(self, *args, **kwargs)
           ^^^^^^^^^^^^^^^^^^^^^^^^^^^
  File "/home/airflow/.local/lib/python3.12/site-packages/airflow/operators/python.py", line 238, in execute
    return_value = self.execute_callable()
                   ^^^^^^^^^^^^^^^^^^^^^^^
  File "/home/airflow/.local/lib/python3.12/site-packages/airflow/operators/python.py", line 256, in execute_callable
    return runner.run(*self.op_args, **self.op_kwargs)
           ^^^^^^^^^^^^^^^^^^^^^^^^^^^^^^^^^^^^^^^^^^^
  File "/home/airflow/.local/lib/python3.12/site-packages/airflow/utils/operator_helpers.py", line 252, in run
    return self.func(*args, **kwargs)
           ^^^^^^^^^^^^^^^^^^^^^^^^^^
  File "/opt/airflow/dags/et_pipeline.py", line 123, in load_and_validate
    validated_gcs_uri = validate_data(gcs_uri)
                        ^^^^^^^^^^^^^^^^^^^^^^
  File "/opt/airflow/dags/et_pipeline.py", line 57, in validate_data
    raise Exception(f"Error while decoding JSON: {str(e)}")
Exception: Error while decoding JSON: Extra data: line 2 column 1 (char 2336)
[2024-11-10T15:19:36.636+0000] {logging_mixin.py:190} INFO - Task instance in failure state
[2024-11-10T15:19:36.639+0000] {logging_mixin.py:190} INFO - Task start:2024-11-10 15:19:31.043182+00:00 end:2024-11-10 15:19:36.634937+00:00 duration:5.591755
[2024-11-10T15:19:36.641+0000] {logging_mixin.py:190} INFO - Task:<Task(PythonOperator): load_and_validate> dag:<DAG: mongodb_atlas_fetch_load> dagrun:<DagRun mongodb_atlas_fetch_load @ 2024-11-10 15:19:14.620848+00:00: manual__2024-11-10T15:19:14.620848+00:00, state:running, queued_at: 2024-11-10 15:19:14.637425+00:00. externally triggered: True>
[2024-11-10T15:19:36.641+0000] {logging_mixin.py:190} INFO - Failure caused by Error while decoding JSON: Extra data: line 2 column 1 (char 2336)
[2024-11-10T15:19:36.642+0000] {taskinstance.py:1225} INFO - Marking task as FAILED. dag_id=mongodb_atlas_fetch_load, task_id=load_and_validate, run_id=manual__2024-11-10T15:19:14.620848+00:00, execution_date=20241110T151914, start_date=20241110T151931, end_date=20241110T151936
[2024-11-10T15:19:36.711+0000] {taskinstance.py:340} INFO - ::group::Post task execution logs
[2024-11-10T15:19:36.715+0000] {standard_task_runner.py:124} ERROR - Failed to execute job 143 for task load_and_validate (Error while decoding JSON: Extra data: line 2 column 1 (char 2336); 720)
Traceback (most recent call last):
  File "/opt/airflow/dags/et_pipeline.py", line 55, in validate_data
    api_data = json.loads(data.decode("utf-8"))
               ^^^^^^^^^^^^^^^^^^^^^^^^^^^^^^^^
  File "/usr/local/lib/python3.12/json/__init__.py", line 346, in loads
    return _default_decoder.decode(s)
           ^^^^^^^^^^^^^^^^^^^^^^^^^^
  File "/usr/local/lib/python3.12/json/decoder.py", line 340, in decode
    raise JSONDecodeError("Extra data", s, end)
json.decoder.JSONDecodeError: Extra data: line 2 column 1 (char 2336)

During handling of the above exception, another exception occurred:

Traceback (most recent call last):
  File "/home/airflow/.local/lib/python3.12/site-packages/airflow/task/task_runner/standard_task_runner.py", line 117, in _start_by_fork
    ret = args.func(args, dag=self.dag)
          ^^^^^^^^^^^^^^^^^^^^^^^^^^^^^
  File "/home/airflow/.local/lib/python3.12/site-packages/airflow/cli/cli_config.py", line 49, in command
    return func(*args, **kwargs)
           ^^^^^^^^^^^^^^^^^^^^^
  File "/home/airflow/.local/lib/python3.12/site-packages/airflow/utils/cli.py", line 116, in wrapper
    return f(*args, **kwargs)
           ^^^^^^^^^^^^^^^^^^
  File "/home/airflow/.local/lib/python3.12/site-packages/airflow/cli/commands/task_command.py", line 483, in task_run
    task_return_code = _run_task_by_selected_method(args, _dag, ti)
                       ^^^^^^^^^^^^^^^^^^^^^^^^^^^^^^^^^^^^^^^^^^^^
  File "/home/airflow/.local/lib/python3.12/site-packages/airflow/cli/commands/task_command.py", line 256, in _run_task_by_selected_method
    return _run_raw_task(args, ti)
           ^^^^^^^^^^^^^^^^^^^^^^^
  File "/home/airflow/.local/lib/python3.12/site-packages/airflow/cli/commands/task_command.py", line 341, in _run_raw_task
    return ti._run_raw_task(
           ^^^^^^^^^^^^^^^^^
  File "/home/airflow/.local/lib/python3.12/site-packages/airflow/utils/session.py", line 97, in wrapper
    return func(*args, session=session, **kwargs)
           ^^^^^^^^^^^^^^^^^^^^^^^^^^^^^^^^^^^^^^
  File "/home/airflow/.local/lib/python3.12/site-packages/airflow/models/taskinstance.py", line 3005, in _run_raw_task
    return _run_raw_task(
           ^^^^^^^^^^^^^^
  File "/home/airflow/.local/lib/python3.12/site-packages/airflow/models/taskinstance.py", line 273, in _run_raw_task
    TaskInstance._execute_task_with_callbacks(
  File "/home/airflow/.local/lib/python3.12/site-packages/airflow/models/taskinstance.py", line 3159, in _execute_task_with_callbacks
    result = self._execute_task(context, task_orig)
             ^^^^^^^^^^^^^^^^^^^^^^^^^^^^^^^^^^^^^^
  File "/home/airflow/.local/lib/python3.12/site-packages/airflow/models/taskinstance.py", line 3183, in _execute_task
    return _execute_task(self, context, task_orig)
           ^^^^^^^^^^^^^^^^^^^^^^^^^^^^^^^^^^^^^^^
  File "/home/airflow/.local/lib/python3.12/site-packages/airflow/models/taskinstance.py", line 767, in _execute_task
    result = _execute_callable(context=context, **execute_callable_kwargs)
             ^^^^^^^^^^^^^^^^^^^^^^^^^^^^^^^^^^^^^^^^^^^^^^^^^^^^^^^^^^^^^
  File "/home/airflow/.local/lib/python3.12/site-packages/airflow/models/taskinstance.py", line 733, in _execute_callable
    return ExecutionCallableRunner(
           ^^^^^^^^^^^^^^^^^^^^^^^^
  File "/home/airflow/.local/lib/python3.12/site-packages/airflow/utils/operator_helpers.py", line 252, in run
    return self.func(*args, **kwargs)
           ^^^^^^^^^^^^^^^^^^^^^^^^^^
  File "/home/airflow/.local/lib/python3.12/site-packages/airflow/models/baseoperator.py", line 417, in wrapper
    return func(self, *args, **kwargs)
           ^^^^^^^^^^^^^^^^^^^^^^^^^^^
  File "/home/airflow/.local/lib/python3.12/site-packages/airflow/operators/python.py", line 238, in execute
    return_value = self.execute_callable()
                   ^^^^^^^^^^^^^^^^^^^^^^^
  File "/home/airflow/.local/lib/python3.12/site-packages/airflow/operators/python.py", line 256, in execute_callable
    return runner.run(*self.op_args, **self.op_kwargs)
           ^^^^^^^^^^^^^^^^^^^^^^^^^^^^^^^^^^^^^^^^^^^
  File "/home/airflow/.local/lib/python3.12/site-packages/airflow/utils/operator_helpers.py", line 252, in run
    return self.func(*args, **kwargs)
           ^^^^^^^^^^^^^^^^^^^^^^^^^^
  File "/opt/airflow/dags/et_pipeline.py", line 123, in load_and_validate
    validated_gcs_uri = validate_data(gcs_uri)
                        ^^^^^^^^^^^^^^^^^^^^^^
  File "/opt/airflow/dags/et_pipeline.py", line 57, in validate_data
    raise Exception(f"Error while decoding JSON: {str(e)}")
Exception: Error while decoding JSON: Extra data: line 2 column 1 (char 2336)
[2024-11-10T15:19:36.766+0000] {local_task_job_runner.py:266} INFO - Task exited with return code 1
[2024-11-10T15:19:36.826+0000] {taskinstance.py:3895} INFO - 0 downstream tasks scheduled from follow-on schedule check
[2024-11-10T15:19:36.835+0000] {local_task_job_runner.py:245} INFO - ::endgroup::
