[2024-11-10T14:35:46.763+0000] {local_task_job_runner.py:123} INFO - ::group::Pre task execution logs
[2024-11-10T14:35:46.796+0000] {taskinstance.py:2613} INFO - Dependencies all met for dep_context=non-requeueable deps ti=<TaskInstance: mongodb_atlas_fetch_load.load_and_validate manual__2024-11-10T14:34:54.786419+00:00 [queued]>
[2024-11-10T14:35:46.813+0000] {taskinstance.py:2613} INFO - Dependencies all met for dep_context=requeueable deps ti=<TaskInstance: mongodb_atlas_fetch_load.load_and_validate manual__2024-11-10T14:34:54.786419+00:00 [queued]>
[2024-11-10T14:35:46.813+0000] {taskinstance.py:2866} INFO - Starting attempt 1 of 1
[2024-11-10T14:35:46.844+0000] {taskinstance.py:2889} INFO - Executing <Task(PythonOperator): load_and_validate> on 2024-11-10 14:34:54.786419+00:00
[2024-11-10T14:35:46.863+0000] {warnings.py:112} WARNING - /home/***/.local/lib/python3.12/site-packages/***/task/task_runner/standard_task_runner.py:70: DeprecationWarning: This process (pid=110) is multi-threaded, use of fork() may lead to deadlocks in the child.
  pid = os.fork()

[2024-11-10T14:35:46.866+0000] {standard_task_runner.py:72} INFO - Started process 112 to run task
[2024-11-10T14:35:46.869+0000] {standard_task_runner.py:104} INFO - Running: ['***', 'tasks', 'run', 'mongodb_atlas_fetch_load', 'load_and_validate', 'manual__2024-11-10T14:34:54.786419+00:00', '--job-id', '132', '--raw', '--subdir', 'DAGS_FOLDER/et_pipeline.py', '--cfg-path', '/tmp/tmpyu6lkpyu']
[2024-11-10T14:35:46.873+0000] {standard_task_runner.py:105} INFO - Job 132: Subtask load_and_validate
[2024-11-10T14:35:46.958+0000] {task_command.py:467} INFO - Running <TaskInstance: mongodb_atlas_fetch_load.load_and_validate manual__2024-11-10T14:34:54.786419+00:00 [running]> on host e9f90922e3c1
[2024-11-10T14:35:47.207+0000] {taskinstance.py:3132} INFO - Exporting env vars: AIRFLOW_CTX_DAG_OWNER='***' AIRFLOW_CTX_DAG_ID='mongodb_atlas_fetch_load' AIRFLOW_CTX_TASK_ID='load_and_validate' AIRFLOW_CTX_EXECUTION_DATE='2024-11-10T14:34:54.786419+00:00' AIRFLOW_CTX_TRY_NUMBER='1' AIRFLOW_CTX_DAG_RUN_ID='manual__2024-11-10T14:34:54.786419+00:00'
[2024-11-10T14:35:47.214+0000] {logging_mixin.py:190} INFO - Task instance is in running state
[2024-11-10T14:35:47.215+0000] {logging_mixin.py:190} INFO -  Previous state of the Task instance: queued
[2024-11-10T14:35:47.219+0000] {logging_mixin.py:190} INFO - Current task name:load_and_validate state:running start_date:2024-11-10 14:35:46.797554+00:00
[2024-11-10T14:35:47.223+0000] {logging_mixin.py:190} INFO - Dag name:mongodb_atlas_fetch_load and current dag run status:running
[2024-11-10T14:35:47.223+0000] {taskinstance.py:731} INFO - ::endgroup::
[2024-11-10T14:35:47.273+0000] {base.py:84} INFO - Retrieving connection 'mongo_default'
[2024-11-10T14:36:35.964+0000] {connection.py:277} WARNING - Connection schemes (type: google_cloud_platform) shall not contain '_' according to RFC3986.
[2024-11-10T14:36:35.974+0000] {base.py:84} INFO - Retrieving connection 'google_cloud_default'
[2024-11-10T14:36:37.836+0000] {gcs.py:594} INFO - File /tmp/mongo_data.json uploaded to raw_data/api_combined_data.json in ***_bucket_name bucket
[2024-11-10T14:36:37.838+0000] {hook.py:208} WARNING - Data lineage tracking is disabled. Register a hook lineage reader to start tracking hook lineage.
[2024-11-10T14:36:37.900+0000] {connection.py:277} WARNING - Connection schemes (type: google_cloud_platform) shall not contain '_' according to RFC3986.
[2024-11-10T14:36:37.902+0000] {base.py:84} INFO - Retrieving connection 'google_cloud_default'
[2024-11-10T14:36:38.097+0000] {hook.py:208} WARNING - Data lineage tracking is disabled. Register a hook lineage reader to start tracking hook lineage.
[2024-11-10T14:36:41.125+0000] {taskinstance.py:3311} ERROR - Task failed with exception
Traceback (most recent call last):
  File "/home/airflow/.local/lib/python3.12/site-packages/airflow/models/taskinstance.py", line 767, in _execute_task
    result = _execute_callable(context=context, **execute_callable_kwargs)
             ^^^^^^^^^^^^^^^^^^^^^^^^^^^^^^^^^^^^^^^^^^^^^^^^^^^^^^^^^^^^^
  File "/home/airflow/.local/lib/python3.12/site-packages/airflow/models/taskinstance.py", line 733, in _execute_callable
    return ExecutionCallableRunner(
           ^^^^^^^^^^^^^^^^^^^^^^^^
  File "/home/airflow/.local/lib/python3.12/site-packages/airflow/utils/operator_helpers.py", line 252, in run
    return self.func(*args, **kwargs)
           ^^^^^^^^^^^^^^^^^^^^^^^^^^
  File "/home/airflow/.local/lib/python3.12/site-packages/airflow/models/baseoperator.py", line 417, in wrapper
    return func(self, *args, **kwargs)
           ^^^^^^^^^^^^^^^^^^^^^^^^^^^
  File "/home/airflow/.local/lib/python3.12/site-packages/airflow/operators/python.py", line 238, in execute
    return_value = self.execute_callable()
                   ^^^^^^^^^^^^^^^^^^^^^^^
  File "/home/airflow/.local/lib/python3.12/site-packages/airflow/operators/python.py", line 256, in execute_callable
    return runner.run(*self.op_args, **self.op_kwargs)
           ^^^^^^^^^^^^^^^^^^^^^^^^^^^^^^^^^^^^^^^^^^^
  File "/home/airflow/.local/lib/python3.12/site-packages/airflow/utils/operator_helpers.py", line 252, in run
    return self.func(*args, **kwargs)
           ^^^^^^^^^^^^^^^^^^^^^^^^^^
  File "/opt/airflow/dags/et_pipeline.py", line 114, in load_and_validate
    validated_gcs_uri = validate_data(gcs_uri)
                        ^^^^^^^^^^^^^^^^^^^^^^
  File "/opt/airflow/dags/et_pipeline.py", line 43, in validate_data
    raise ValueError(f"Data validation failed: missing required fields")
ValueError: Data validation failed: missing required fields
[2024-11-10T14:36:41.177+0000] {logging_mixin.py:190} INFO - Task instance in failure state
[2024-11-10T14:36:41.178+0000] {logging_mixin.py:190} INFO - Task start:2024-11-10 14:35:46.797554+00:00 end:2024-11-10 14:36:41.170819+00:00 duration:54.373265
[2024-11-10T14:36:41.179+0000] {logging_mixin.py:190} INFO - Task:<Task(PythonOperator): load_and_validate> dag:<DAG: mongodb_atlas_fetch_load> dagrun:<DagRun mongodb_atlas_fetch_load @ 2024-11-10 14:34:54.786419+00:00: manual__2024-11-10T14:34:54.786419+00:00, state:running, queued_at: 2024-11-10 14:34:54.817832+00:00. externally triggered: True>
[2024-11-10T14:36:41.181+0000] {logging_mixin.py:190} INFO - Failure caused by Data validation failed: missing required fields
[2024-11-10T14:36:41.183+0000] {taskinstance.py:1225} INFO - Marking task as FAILED. dag_id=mongodb_atlas_fetch_load, task_id=load_and_validate, run_id=manual__2024-11-10T14:34:54.786419+00:00, execution_date=20241110T143454, start_date=20241110T143546, end_date=20241110T143641
[2024-11-10T14:36:41.239+0000] {taskinstance.py:340} INFO - ::group::Post task execution logs
[2024-11-10T14:36:41.242+0000] {standard_task_runner.py:124} ERROR - Failed to execute job 132 for task load_and_validate (Data validation failed: missing required fields; 112)
Traceback (most recent call last):
  File "/home/airflow/.local/lib/python3.12/site-packages/airflow/task/task_runner/standard_task_runner.py", line 117, in _start_by_fork
    ret = args.func(args, dag=self.dag)
          ^^^^^^^^^^^^^^^^^^^^^^^^^^^^^
  File "/home/airflow/.local/lib/python3.12/site-packages/airflow/cli/cli_config.py", line 49, in command
    return func(*args, **kwargs)
           ^^^^^^^^^^^^^^^^^^^^^
  File "/home/airflow/.local/lib/python3.12/site-packages/airflow/utils/cli.py", line 116, in wrapper
    return f(*args, **kwargs)
           ^^^^^^^^^^^^^^^^^^
  File "/home/airflow/.local/lib/python3.12/site-packages/airflow/cli/commands/task_command.py", line 483, in task_run
    task_return_code = _run_task_by_selected_method(args, _dag, ti)
                       ^^^^^^^^^^^^^^^^^^^^^^^^^^^^^^^^^^^^^^^^^^^^
  File "/home/airflow/.local/lib/python3.12/site-packages/airflow/cli/commands/task_command.py", line 256, in _run_task_by_selected_method
    return _run_raw_task(args, ti)
           ^^^^^^^^^^^^^^^^^^^^^^^
  File "/home/airflow/.local/lib/python3.12/site-packages/airflow/cli/commands/task_command.py", line 341, in _run_raw_task
    return ti._run_raw_task(
           ^^^^^^^^^^^^^^^^^
  File "/home/airflow/.local/lib/python3.12/site-packages/airflow/utils/session.py", line 97, in wrapper
    return func(*args, session=session, **kwargs)
           ^^^^^^^^^^^^^^^^^^^^^^^^^^^^^^^^^^^^^^
  File "/home/airflow/.local/lib/python3.12/site-packages/airflow/models/taskinstance.py", line 3005, in _run_raw_task
    return _run_raw_task(
           ^^^^^^^^^^^^^^
  File "/home/airflow/.local/lib/python3.12/site-packages/airflow/models/taskinstance.py", line 273, in _run_raw_task
    TaskInstance._execute_task_with_callbacks(
  File "/home/airflow/.local/lib/python3.12/site-packages/airflow/models/taskinstance.py", line 3159, in _execute_task_with_callbacks
    result = self._execute_task(context, task_orig)
             ^^^^^^^^^^^^^^^^^^^^^^^^^^^^^^^^^^^^^^
  File "/home/airflow/.local/lib/python3.12/site-packages/airflow/models/taskinstance.py", line 3183, in _execute_task
    return _execute_task(self, context, task_orig)
           ^^^^^^^^^^^^^^^^^^^^^^^^^^^^^^^^^^^^^^^
  File "/home/airflow/.local/lib/python3.12/site-packages/airflow/models/taskinstance.py", line 767, in _execute_task
    result = _execute_callable(context=context, **execute_callable_kwargs)
             ^^^^^^^^^^^^^^^^^^^^^^^^^^^^^^^^^^^^^^^^^^^^^^^^^^^^^^^^^^^^^
  File "/home/airflow/.local/lib/python3.12/site-packages/airflow/models/taskinstance.py", line 733, in _execute_callable
    return ExecutionCallableRunner(
           ^^^^^^^^^^^^^^^^^^^^^^^^
  File "/home/airflow/.local/lib/python3.12/site-packages/airflow/utils/operator_helpers.py", line 252, in run
    return self.func(*args, **kwargs)
           ^^^^^^^^^^^^^^^^^^^^^^^^^^
  File "/home/airflow/.local/lib/python3.12/site-packages/airflow/models/baseoperator.py", line 417, in wrapper
    return func(self, *args, **kwargs)
           ^^^^^^^^^^^^^^^^^^^^^^^^^^^
  File "/home/airflow/.local/lib/python3.12/site-packages/airflow/operators/python.py", line 238, in execute
    return_value = self.execute_callable()
                   ^^^^^^^^^^^^^^^^^^^^^^^
  File "/home/airflow/.local/lib/python3.12/site-packages/airflow/operators/python.py", line 256, in execute_callable
    return runner.run(*self.op_args, **self.op_kwargs)
           ^^^^^^^^^^^^^^^^^^^^^^^^^^^^^^^^^^^^^^^^^^^
  File "/home/airflow/.local/lib/python3.12/site-packages/airflow/utils/operator_helpers.py", line 252, in run
    return self.func(*args, **kwargs)
           ^^^^^^^^^^^^^^^^^^^^^^^^^^
  File "/opt/airflow/dags/et_pipeline.py", line 114, in load_and_validate
    validated_gcs_uri = validate_data(gcs_uri)
                        ^^^^^^^^^^^^^^^^^^^^^^
  File "/opt/airflow/dags/et_pipeline.py", line 43, in validate_data
    raise ValueError(f"Data validation failed: missing required fields")
ValueError: Data validation failed: missing required fields
[2024-11-10T14:36:41.307+0000] {local_task_job_runner.py:266} INFO - Task exited with return code 1
[2024-11-10T14:36:41.413+0000] {taskinstance.py:3895} INFO - 0 downstream tasks scheduled from follow-on schedule check
[2024-11-10T14:36:41.429+0000] {local_task_job_runner.py:245} INFO - ::endgroup::
