[2024-11-09T20:07:15.411+0000] {local_task_job_runner.py:123} INFO - ::group::Pre task execution logs
[2024-11-09T20:07:15.446+0000] {taskinstance.py:2613} INFO - Dependencies all met for dep_context=non-requeueable deps ti=<TaskInstance: mongodb_atlas_fetch_load_data.load_data manual__2024-11-09T20:07:07.126541+00:00 [queued]>
[2024-11-09T20:07:15.463+0000] {taskinstance.py:2613} INFO - Dependencies all met for dep_context=requeueable deps ti=<TaskInstance: mongodb_atlas_fetch_load_data.load_data manual__2024-11-09T20:07:07.126541+00:00 [queued]>
[2024-11-09T20:07:15.463+0000] {taskinstance.py:2866} INFO - Starting attempt 1 of 1
[2024-11-09T20:07:15.510+0000] {taskinstance.py:2889} INFO - Executing <Task(PythonOperator): load_data> on 2024-11-09 20:07:07.126541+00:00
[2024-11-09T20:07:15.539+0000] {warnings.py:112} WARNING - /home/***/.local/lib/python3.12/site-packages/***/task/task_runner/standard_task_runner.py:70: DeprecationWarning: This process (pid=1159) is multi-threaded, use of fork() may lead to deadlocks in the child.
  pid = os.fork()

[2024-11-09T20:07:15.544+0000] {standard_task_runner.py:72} INFO - Started process 1161 to run task
[2024-11-09T20:07:15.556+0000] {standard_task_runner.py:104} INFO - Running: ['***', 'tasks', 'run', 'mongodb_atlas_fetch_load_data', 'load_data', 'manual__2024-11-09T20:07:07.126541+00:00', '--job-id', '83', '--raw', '--subdir', 'DAGS_FOLDER/et_pipeline.py', '--cfg-path', '/tmp/tmp790p62el']
[2024-11-09T20:07:15.559+0000] {standard_task_runner.py:105} INFO - Job 83: Subtask load_data
[2024-11-09T20:07:15.712+0000] {task_command.py:467} INFO - Running <TaskInstance: mongodb_atlas_fetch_load_data.load_data manual__2024-11-09T20:07:07.126541+00:00 [running]> on host c81164041ce5
[2024-11-09T20:07:15.999+0000] {taskinstance.py:3132} INFO - Exporting env vars: AIRFLOW_CTX_DAG_OWNER='***' AIRFLOW_CTX_DAG_ID='mongodb_atlas_fetch_load_data' AIRFLOW_CTX_TASK_ID='load_data' AIRFLOW_CTX_EXECUTION_DATE='2024-11-09T20:07:07.126541+00:00' AIRFLOW_CTX_TRY_NUMBER='1' AIRFLOW_CTX_DAG_RUN_ID='manual__2024-11-09T20:07:07.126541+00:00'
[2024-11-09T20:07:16.003+0000] {logging_mixin.py:190} INFO - Task instance is in running state
[2024-11-09T20:07:16.005+0000] {logging_mixin.py:190} INFO -  Previous state of the Task instance: queued
[2024-11-09T20:07:16.006+0000] {logging_mixin.py:190} INFO - Current task name:load_data state:running start_date:2024-11-09 20:07:15.446520+00:00
[2024-11-09T20:07:16.006+0000] {logging_mixin.py:190} INFO - Dag name:mongodb_atlas_fetch_load_data and current dag run status:running
[2024-11-09T20:07:16.007+0000] {taskinstance.py:731} INFO - ::endgroup::
[2024-11-09T20:07:16.029+0000] {taskinstance.py:3311} ERROR - Task failed with exception
Traceback (most recent call last):
  File "/home/airflow/.local/lib/python3.12/site-packages/airflow/models/taskinstance.py", line 767, in _execute_task
    result = _execute_callable(context=context, **execute_callable_kwargs)
             ^^^^^^^^^^^^^^^^^^^^^^^^^^^^^^^^^^^^^^^^^^^^^^^^^^^^^^^^^^^^^
  File "/home/airflow/.local/lib/python3.12/site-packages/airflow/models/taskinstance.py", line 733, in _execute_callable
    return ExecutionCallableRunner(
           ^^^^^^^^^^^^^^^^^^^^^^^^
  File "/home/airflow/.local/lib/python3.12/site-packages/airflow/utils/operator_helpers.py", line 252, in run
    return self.func(*args, **kwargs)
           ^^^^^^^^^^^^^^^^^^^^^^^^^^
  File "/home/airflow/.local/lib/python3.12/site-packages/airflow/models/baseoperator.py", line 417, in wrapper
    return func(self, *args, **kwargs)
           ^^^^^^^^^^^^^^^^^^^^^^^^^^^
  File "/home/airflow/.local/lib/python3.12/site-packages/airflow/operators/python.py", line 238, in execute
    return_value = self.execute_callable()
                   ^^^^^^^^^^^^^^^^^^^^^^^
  File "/home/airflow/.local/lib/python3.12/site-packages/airflow/operators/python.py", line 256, in execute_callable
    return runner.run(*self.op_args, **self.op_kwargs)
           ^^^^^^^^^^^^^^^^^^^^^^^^^^^^^^^^^^^^^^^^^^^
  File "/home/airflow/.local/lib/python3.12/site-packages/airflow/utils/operator_helpers.py", line 252, in run
    return self.func(*args, **kwargs)
           ^^^^^^^^^^^^^^^^^^^^^^^^^^
  File "/opt/airflow/dags/et_pipeline.py", line 66, in <lambda>
    python_callable=lambda **kwargs: gcp_load(kwargs['ti'].xcom_pull(task_ids='fetch_data'), **kwargs),
                                     ^^^^^^^^^^^^^^^^^^^^^^^^^^^^^^^^^^^^^^^^^^^^^^^^^^^^^^^^^^^^^^^^^
  File "/opt/airflow/dags/et_pipeline.py", line 24, in gcp_load
    raise ValueError("Invalid file path provided to gcp_load.")
ValueError: Invalid file path provided to gcp_load.
[2024-11-09T20:07:16.055+0000] {logging_mixin.py:190} INFO - Task instance in failure state
[2024-11-09T20:07:16.056+0000] {logging_mixin.py:190} INFO - Task start:2024-11-09 20:07:15.446520+00:00 end:2024-11-09 20:07:16.054399+00:00 duration:0.607879
[2024-11-09T20:07:16.057+0000] {logging_mixin.py:190} INFO - Task:<Task(PythonOperator): load_data> dag:<DAG: mongodb_atlas_fetch_load_data> dagrun:<DagRun mongodb_atlas_fetch_load_data @ 2024-11-09 20:07:07.126541+00:00: manual__2024-11-09T20:07:07.126541+00:00, state:running, queued_at: 2024-11-09 20:07:07.176519+00:00. externally triggered: True>
[2024-11-09T20:07:16.057+0000] {logging_mixin.py:190} INFO - Failure caused by Invalid file path provided to gcp_load.
[2024-11-09T20:07:16.058+0000] {taskinstance.py:1225} INFO - Marking task as FAILED. dag_id=mongodb_atlas_fetch_load_data, task_id=load_data, run_id=manual__2024-11-09T20:07:07.126541+00:00, execution_date=20241109T200707, start_date=20241109T200715, end_date=20241109T200716
[2024-11-09T20:07:16.091+0000] {taskinstance.py:340} INFO - ::group::Post task execution logs
[2024-11-09T20:07:16.092+0000] {standard_task_runner.py:124} ERROR - Failed to execute job 83 for task load_data (Invalid file path provided to gcp_load.; 1161)
Traceback (most recent call last):
  File "/home/airflow/.local/lib/python3.12/site-packages/airflow/task/task_runner/standard_task_runner.py", line 117, in _start_by_fork
    ret = args.func(args, dag=self.dag)
          ^^^^^^^^^^^^^^^^^^^^^^^^^^^^^
  File "/home/airflow/.local/lib/python3.12/site-packages/airflow/cli/cli_config.py", line 49, in command
    return func(*args, **kwargs)
           ^^^^^^^^^^^^^^^^^^^^^
  File "/home/airflow/.local/lib/python3.12/site-packages/airflow/utils/cli.py", line 116, in wrapper
    return f(*args, **kwargs)
           ^^^^^^^^^^^^^^^^^^
  File "/home/airflow/.local/lib/python3.12/site-packages/airflow/cli/commands/task_command.py", line 483, in task_run
    task_return_code = _run_task_by_selected_method(args, _dag, ti)
                       ^^^^^^^^^^^^^^^^^^^^^^^^^^^^^^^^^^^^^^^^^^^^
  File "/home/airflow/.local/lib/python3.12/site-packages/airflow/cli/commands/task_command.py", line 256, in _run_task_by_selected_method
    return _run_raw_task(args, ti)
           ^^^^^^^^^^^^^^^^^^^^^^^
  File "/home/airflow/.local/lib/python3.12/site-packages/airflow/cli/commands/task_command.py", line 341, in _run_raw_task
    return ti._run_raw_task(
           ^^^^^^^^^^^^^^^^^
  File "/home/airflow/.local/lib/python3.12/site-packages/airflow/utils/session.py", line 97, in wrapper
    return func(*args, session=session, **kwargs)
           ^^^^^^^^^^^^^^^^^^^^^^^^^^^^^^^^^^^^^^
  File "/home/airflow/.local/lib/python3.12/site-packages/airflow/models/taskinstance.py", line 3005, in _run_raw_task
    return _run_raw_task(
           ^^^^^^^^^^^^^^
  File "/home/airflow/.local/lib/python3.12/site-packages/airflow/models/taskinstance.py", line 273, in _run_raw_task
    TaskInstance._execute_task_with_callbacks(
  File "/home/airflow/.local/lib/python3.12/site-packages/airflow/models/taskinstance.py", line 3159, in _execute_task_with_callbacks
    result = self._execute_task(context, task_orig)
             ^^^^^^^^^^^^^^^^^^^^^^^^^^^^^^^^^^^^^^
  File "/home/airflow/.local/lib/python3.12/site-packages/airflow/models/taskinstance.py", line 3183, in _execute_task
    return _execute_task(self, context, task_orig)
           ^^^^^^^^^^^^^^^^^^^^^^^^^^^^^^^^^^^^^^^
  File "/home/airflow/.local/lib/python3.12/site-packages/airflow/models/taskinstance.py", line 767, in _execute_task
    result = _execute_callable(context=context, **execute_callable_kwargs)
             ^^^^^^^^^^^^^^^^^^^^^^^^^^^^^^^^^^^^^^^^^^^^^^^^^^^^^^^^^^^^^
  File "/home/airflow/.local/lib/python3.12/site-packages/airflow/models/taskinstance.py", line 733, in _execute_callable
    return ExecutionCallableRunner(
           ^^^^^^^^^^^^^^^^^^^^^^^^
  File "/home/airflow/.local/lib/python3.12/site-packages/airflow/utils/operator_helpers.py", line 252, in run
    return self.func(*args, **kwargs)
           ^^^^^^^^^^^^^^^^^^^^^^^^^^
  File "/home/airflow/.local/lib/python3.12/site-packages/airflow/models/baseoperator.py", line 417, in wrapper
    return func(self, *args, **kwargs)
           ^^^^^^^^^^^^^^^^^^^^^^^^^^^
  File "/home/airflow/.local/lib/python3.12/site-packages/airflow/operators/python.py", line 238, in execute
    return_value = self.execute_callable()
                   ^^^^^^^^^^^^^^^^^^^^^^^
  File "/home/airflow/.local/lib/python3.12/site-packages/airflow/operators/python.py", line 256, in execute_callable
    return runner.run(*self.op_args, **self.op_kwargs)
           ^^^^^^^^^^^^^^^^^^^^^^^^^^^^^^^^^^^^^^^^^^^
  File "/home/airflow/.local/lib/python3.12/site-packages/airflow/utils/operator_helpers.py", line 252, in run
    return self.func(*args, **kwargs)
           ^^^^^^^^^^^^^^^^^^^^^^^^^^
  File "/opt/airflow/dags/et_pipeline.py", line 66, in <lambda>
    python_callable=lambda **kwargs: gcp_load(kwargs['ti'].xcom_pull(task_ids='fetch_data'), **kwargs),
                                     ^^^^^^^^^^^^^^^^^^^^^^^^^^^^^^^^^^^^^^^^^^^^^^^^^^^^^^^^^^^^^^^^^
  File "/opt/airflow/dags/et_pipeline.py", line 24, in gcp_load
    raise ValueError("Invalid file path provided to gcp_load.")
ValueError: Invalid file path provided to gcp_load.
[2024-11-09T20:07:16.130+0000] {local_task_job_runner.py:266} INFO - Task exited with return code 1
[2024-11-09T20:07:16.178+0000] {taskinstance.py:3895} INFO - 0 downstream tasks scheduled from follow-on schedule check
[2024-11-09T20:07:16.182+0000] {local_task_job_runner.py:245} INFO - ::endgroup::
