[2024-11-10T14:55:05.417+0000] {local_task_job_runner.py:123} INFO - ::group::Pre task execution logs
[2024-11-10T14:55:05.455+0000] {taskinstance.py:2613} INFO - Dependencies all met for dep_context=non-requeueable deps ti=<TaskInstance: mongodb_atlas_fetch_load.load_to_bigquery manual__2024-11-10T14:53:24.067482+00:00 [queued]>
[2024-11-10T14:55:05.472+0000] {taskinstance.py:2613} INFO - Dependencies all met for dep_context=requeueable deps ti=<TaskInstance: mongodb_atlas_fetch_load.load_to_bigquery manual__2024-11-10T14:53:24.067482+00:00 [queued]>
[2024-11-10T14:55:05.473+0000] {taskinstance.py:2866} INFO - Starting attempt 1 of 1
[2024-11-10T14:55:05.503+0000] {taskinstance.py:2889} INFO - Executing <Task(PythonOperator): load_to_bigquery> on 2024-11-10 14:53:24.067482+00:00
[2024-11-10T14:55:05.521+0000] {warnings.py:112} WARNING - /home/***/.local/lib/python3.12/site-packages/***/task/task_runner/standard_task_runner.py:70: DeprecationWarning: This process (pid=355) is multi-threaded, use of fork() may lead to deadlocks in the child.
  pid = os.fork()

[2024-11-10T14:55:05.525+0000] {standard_task_runner.py:72} INFO - Started process 357 to run task
[2024-11-10T14:55:05.527+0000] {standard_task_runner.py:104} INFO - Running: ['***', 'tasks', 'run', 'mongodb_atlas_fetch_load', 'load_to_bigquery', 'manual__2024-11-10T14:53:24.067482+00:00', '--job-id', '135', '--raw', '--subdir', 'DAGS_FOLDER/et_pipeline.py', '--cfg-path', '/tmp/tmpwyxxvj53']
[2024-11-10T14:55:05.530+0000] {standard_task_runner.py:105} INFO - Job 135: Subtask load_to_bigquery
[2024-11-10T14:55:05.624+0000] {task_command.py:467} INFO - Running <TaskInstance: mongodb_atlas_fetch_load.load_to_bigquery manual__2024-11-10T14:53:24.067482+00:00 [running]> on host e9f90922e3c1
[2024-11-10T14:55:05.827+0000] {taskinstance.py:3132} INFO - Exporting env vars: AIRFLOW_CTX_DAG_OWNER='***' AIRFLOW_CTX_DAG_ID='mongodb_atlas_fetch_load' AIRFLOW_CTX_TASK_ID='load_to_bigquery' AIRFLOW_CTX_EXECUTION_DATE='2024-11-10T14:53:24.067482+00:00' AIRFLOW_CTX_TRY_NUMBER='1' AIRFLOW_CTX_DAG_RUN_ID='manual__2024-11-10T14:53:24.067482+00:00'
[2024-11-10T14:55:05.830+0000] {logging_mixin.py:190} INFO - Task instance is in running state
[2024-11-10T14:55:05.831+0000] {logging_mixin.py:190} INFO -  Previous state of the Task instance: queued
[2024-11-10T14:55:05.831+0000] {logging_mixin.py:190} INFO - Current task name:load_to_bigquery state:running start_date:2024-11-10 14:55:05.456088+00:00
[2024-11-10T14:55:05.832+0000] {logging_mixin.py:190} INFO - Dag name:mongodb_atlas_fetch_load and current dag run status:running
[2024-11-10T14:55:05.833+0000] {taskinstance.py:731} INFO - ::endgroup::
[2024-11-10T14:55:05.856+0000] {base.py:84} INFO - Retrieving connection 'mongo_default'
[2024-11-10T14:55:47.033+0000] {connection.py:277} WARNING - Connection schemes (type: google_cloud_platform) shall not contain '_' according to RFC3986.
[2024-11-10T14:55:47.035+0000] {base.py:84} INFO - Retrieving connection 'google_cloud_default'
[2024-11-10T14:55:47.215+0000] {connection.py:277} WARNING - Connection schemes (type: google_cloud_platform) shall not contain '_' according to RFC3986.
[2024-11-10T14:55:47.216+0000] {base.py:84} INFO - Retrieving connection 'google_cloud_default'
[2024-11-10T14:55:48.708+0000] {gcs.py:594} INFO - File /tmp/mongo_data.json uploaded to transformed_data/mongo_data.json in ***_bucket_name bucket
[2024-11-10T14:55:48.711+0000] {hook.py:208} WARNING - Data lineage tracking is disabled. Register a hook lineage reader to start tracking hook lineage.
[2024-11-10T14:55:50.808+0000] {taskinstance.py:3311} ERROR - Task failed with exception
Traceback (most recent call last):
  File "/home/airflow/.local/lib/python3.12/site-packages/airflow/models/taskinstance.py", line 767, in _execute_task
    result = _execute_callable(context=context, **execute_callable_kwargs)
             ^^^^^^^^^^^^^^^^^^^^^^^^^^^^^^^^^^^^^^^^^^^^^^^^^^^^^^^^^^^^^
  File "/home/airflow/.local/lib/python3.12/site-packages/airflow/models/taskinstance.py", line 733, in _execute_callable
    return ExecutionCallableRunner(
           ^^^^^^^^^^^^^^^^^^^^^^^^
  File "/home/airflow/.local/lib/python3.12/site-packages/airflow/utils/operator_helpers.py", line 252, in run
    return self.func(*args, **kwargs)
           ^^^^^^^^^^^^^^^^^^^^^^^^^^
  File "/home/airflow/.local/lib/python3.12/site-packages/airflow/models/baseoperator.py", line 417, in wrapper
    return func(self, *args, **kwargs)
           ^^^^^^^^^^^^^^^^^^^^^^^^^^^
  File "/home/airflow/.local/lib/python3.12/site-packages/airflow/operators/python.py", line 238, in execute
    return_value = self.execute_callable()
                   ^^^^^^^^^^^^^^^^^^^^^^^
  File "/home/airflow/.local/lib/python3.12/site-packages/airflow/operators/python.py", line 256, in execute_callable
    return runner.run(*self.op_args, **self.op_kwargs)
           ^^^^^^^^^^^^^^^^^^^^^^^^^^^^^^^^^^^^^^^^^^^
  File "/home/airflow/.local/lib/python3.12/site-packages/airflow/utils/operator_helpers.py", line 252, in run
    return self.func(*args, **kwargs)
           ^^^^^^^^^^^^^^^^^^^^^^^^^^
  File "/opt/airflow/dags/et_pipeline.py", line 122, in load_to_bigquery
    load_data_to_bigquery(local_file_path, "arcticls_dataset", "Articls")
  File "/opt/airflow/dags/et_pipeline.py", line 83, in load_data_to_bigquery
    load_job.result()  # Attendre que le job se termine
    ^^^^^^^^^^^^^^^^^
  File "/home/airflow/.local/lib/python3.12/site-packages/google/cloud/bigquery/job/base.py", line 971, in result
    return super(_AsyncJob, self).result(timeout=timeout, **kwargs)
           ^^^^^^^^^^^^^^^^^^^^^^^^^^^^^^^^^^^^^^^^^^^^^^^^^^^^^^^^
  File "/home/airflow/.local/lib/python3.12/site-packages/google/api_core/future/polling.py", line 261, in result
    raise self._exception
google.api_core.exceptions.BadRequest: 400 Error while reading data, error message: JSON table encountered too many errors, giving up. Rows: 1; errors: 1. Please look into the errors[] collection for more details. File: gs://airflow_bucket_name/transformed_data/mongo_data.json; reason: invalid, location: gs://airflow_bucket_name/transformed_data/mongo_data.json, message: Error while reading data, error message: JSON table encountered too many errors, giving up. Rows: 1; errors: 1. Please look into the errors[] collection for more details. File: gs://airflow_bucket_name/transformed_data/mongo_data.json; reason: invalid, message: Error while reading data, error message: JSON processing encountered too many errors, giving up. Rows: 1; errors: 1; max bad: 0; error percent: 0; reason: invalid, location: gs://airflow_bucket_name/transformed_data/mongo_data.json, message: Error while reading data, error message: JSON parsing error in row starting at position 0: Start of array encountered without start of object. File: gs://airflow_bucket_name/transformed_data/mongo_data.json
[2024-11-10T14:55:50.832+0000] {logging_mixin.py:190} INFO - Task instance in failure state
[2024-11-10T14:55:50.833+0000] {logging_mixin.py:190} INFO - Task start:2024-11-10 14:55:05.456088+00:00 end:2024-11-10 14:55:50.830994+00:00 duration:45.374906
[2024-11-10T14:55:50.834+0000] {logging_mixin.py:190} INFO - Task:<Task(PythonOperator): load_to_bigquery> dag:<DAG: mongodb_atlas_fetch_load> dagrun:<DagRun mongodb_atlas_fetch_load @ 2024-11-10 14:53:24.067482+00:00: manual__2024-11-10T14:53:24.067482+00:00, state:running, queued_at: 2024-11-10 14:53:24.158307+00:00. externally triggered: True>
[2024-11-10T14:55:50.835+0000] {logging_mixin.py:190} INFO - Failure caused by 400 Error while reading data, error message: JSON table encountered too many errors, giving up. Rows: 1; errors: 1. Please look into the errors[] collection for more details. File: gs://***_bucket_name/transformed_data/mongo_data.json; reason: invalid, location: gs://***_bucket_name/transformed_data/mongo_data.json, message: Error while reading data, error message: JSON table encountered too many errors, giving up. Rows: 1; errors: 1. Please look into the errors[] collection for more details. File: gs://***_bucket_name/transformed_data/mongo_data.json; reason: invalid, message: Error while reading data, error message: JSON processing encountered too many errors, giving up. Rows: 1; errors: 1; max bad: 0; error percent: 0; reason: invalid, location: gs://***_bucket_name/transformed_data/mongo_data.json, message: Error while reading data, error message: JSON parsing error in row starting at position 0: Start of array encountered without start of object. File: gs://***_bucket_name/transformed_data/mongo_data.json
[2024-11-10T14:55:50.837+0000] {taskinstance.py:1225} INFO - Marking task as FAILED. dag_id=mongodb_atlas_fetch_load, task_id=load_to_bigquery, run_id=manual__2024-11-10T14:53:24.067482+00:00, execution_date=20241110T145324, start_date=20241110T145505, end_date=20241110T145550
[2024-11-10T14:55:50.868+0000] {taskinstance.py:340} INFO - ::group::Post task execution logs
[2024-11-10T14:55:50.870+0000] {standard_task_runner.py:124} ERROR - Failed to execute job 135 for task load_to_bigquery (400 Error while reading data, error message: JSON table encountered too many errors, giving up. Rows: 1; errors: 1. Please look into the errors[] collection for more details. File: gs://airflow_bucket_name/transformed_data/mongo_data.json; reason: invalid, location: gs://airflow_bucket_name/transformed_data/mongo_data.json, message: Error while reading data, error message: JSON table encountered too many errors, giving up. Rows: 1; errors: 1. Please look into the errors[] collection for more details. File: gs://airflow_bucket_name/transformed_data/mongo_data.json; reason: invalid, message: Error while reading data, error message: JSON processing encountered too many errors, giving up. Rows: 1; errors: 1; max bad: 0; error percent: 0; reason: invalid, location: gs://airflow_bucket_name/transformed_data/mongo_data.json, message: Error while reading data, error message: JSON parsing error in row starting at position 0: Start of array encountered without start of object. File: gs://airflow_bucket_name/transformed_data/mongo_data.json; 357)
Traceback (most recent call last):
  File "/home/airflow/.local/lib/python3.12/site-packages/airflow/task/task_runner/standard_task_runner.py", line 117, in _start_by_fork
    ret = args.func(args, dag=self.dag)
          ^^^^^^^^^^^^^^^^^^^^^^^^^^^^^
  File "/home/airflow/.local/lib/python3.12/site-packages/airflow/cli/cli_config.py", line 49, in command
    return func(*args, **kwargs)
           ^^^^^^^^^^^^^^^^^^^^^
  File "/home/airflow/.local/lib/python3.12/site-packages/airflow/utils/cli.py", line 116, in wrapper
    return f(*args, **kwargs)
           ^^^^^^^^^^^^^^^^^^
  File "/home/airflow/.local/lib/python3.12/site-packages/airflow/cli/commands/task_command.py", line 483, in task_run
    task_return_code = _run_task_by_selected_method(args, _dag, ti)
                       ^^^^^^^^^^^^^^^^^^^^^^^^^^^^^^^^^^^^^^^^^^^^
  File "/home/airflow/.local/lib/python3.12/site-packages/airflow/cli/commands/task_command.py", line 256, in _run_task_by_selected_method
    return _run_raw_task(args, ti)
           ^^^^^^^^^^^^^^^^^^^^^^^
  File "/home/airflow/.local/lib/python3.12/site-packages/airflow/cli/commands/task_command.py", line 341, in _run_raw_task
    return ti._run_raw_task(
           ^^^^^^^^^^^^^^^^^
  File "/home/airflow/.local/lib/python3.12/site-packages/airflow/utils/session.py", line 97, in wrapper
    return func(*args, session=session, **kwargs)
           ^^^^^^^^^^^^^^^^^^^^^^^^^^^^^^^^^^^^^^
  File "/home/airflow/.local/lib/python3.12/site-packages/airflow/models/taskinstance.py", line 3005, in _run_raw_task
    return _run_raw_task(
           ^^^^^^^^^^^^^^
  File "/home/airflow/.local/lib/python3.12/site-packages/airflow/models/taskinstance.py", line 273, in _run_raw_task
    TaskInstance._execute_task_with_callbacks(
  File "/home/airflow/.local/lib/python3.12/site-packages/airflow/models/taskinstance.py", line 3159, in _execute_task_with_callbacks
    result = self._execute_task(context, task_orig)
             ^^^^^^^^^^^^^^^^^^^^^^^^^^^^^^^^^^^^^^
  File "/home/airflow/.local/lib/python3.12/site-packages/airflow/models/taskinstance.py", line 3183, in _execute_task
    return _execute_task(self, context, task_orig)
           ^^^^^^^^^^^^^^^^^^^^^^^^^^^^^^^^^^^^^^^
  File "/home/airflow/.local/lib/python3.12/site-packages/airflow/models/taskinstance.py", line 767, in _execute_task
    result = _execute_callable(context=context, **execute_callable_kwargs)
             ^^^^^^^^^^^^^^^^^^^^^^^^^^^^^^^^^^^^^^^^^^^^^^^^^^^^^^^^^^^^^
  File "/home/airflow/.local/lib/python3.12/site-packages/airflow/models/taskinstance.py", line 733, in _execute_callable
    return ExecutionCallableRunner(
           ^^^^^^^^^^^^^^^^^^^^^^^^
  File "/home/airflow/.local/lib/python3.12/site-packages/airflow/utils/operator_helpers.py", line 252, in run
    return self.func(*args, **kwargs)
           ^^^^^^^^^^^^^^^^^^^^^^^^^^
  File "/home/airflow/.local/lib/python3.12/site-packages/airflow/models/baseoperator.py", line 417, in wrapper
    return func(self, *args, **kwargs)
           ^^^^^^^^^^^^^^^^^^^^^^^^^^^
  File "/home/airflow/.local/lib/python3.12/site-packages/airflow/operators/python.py", line 238, in execute
    return_value = self.execute_callable()
                   ^^^^^^^^^^^^^^^^^^^^^^^
  File "/home/airflow/.local/lib/python3.12/site-packages/airflow/operators/python.py", line 256, in execute_callable
    return runner.run(*self.op_args, **self.op_kwargs)
           ^^^^^^^^^^^^^^^^^^^^^^^^^^^^^^^^^^^^^^^^^^^
  File "/home/airflow/.local/lib/python3.12/site-packages/airflow/utils/operator_helpers.py", line 252, in run
    return self.func(*args, **kwargs)
           ^^^^^^^^^^^^^^^^^^^^^^^^^^
  File "/opt/airflow/dags/et_pipeline.py", line 122, in load_to_bigquery
    load_data_to_bigquery(local_file_path, "arcticls_dataset", "Articls")
  File "/opt/airflow/dags/et_pipeline.py", line 83, in load_data_to_bigquery
    load_job.result()  # Attendre que le job se termine
    ^^^^^^^^^^^^^^^^^
  File "/home/airflow/.local/lib/python3.12/site-packages/google/cloud/bigquery/job/base.py", line 971, in result
    return super(_AsyncJob, self).result(timeout=timeout, **kwargs)
           ^^^^^^^^^^^^^^^^^^^^^^^^^^^^^^^^^^^^^^^^^^^^^^^^^^^^^^^^
  File "/home/airflow/.local/lib/python3.12/site-packages/google/api_core/future/polling.py", line 261, in result
    raise self._exception
google.api_core.exceptions.BadRequest: 400 Error while reading data, error message: JSON table encountered too many errors, giving up. Rows: 1; errors: 1. Please look into the errors[] collection for more details. File: gs://airflow_bucket_name/transformed_data/mongo_data.json; reason: invalid, location: gs://airflow_bucket_name/transformed_data/mongo_data.json, message: Error while reading data, error message: JSON table encountered too many errors, giving up. Rows: 1; errors: 1. Please look into the errors[] collection for more details. File: gs://airflow_bucket_name/transformed_data/mongo_data.json; reason: invalid, message: Error while reading data, error message: JSON processing encountered too many errors, giving up. Rows: 1; errors: 1; max bad: 0; error percent: 0; reason: invalid, location: gs://airflow_bucket_name/transformed_data/mongo_data.json, message: Error while reading data, error message: JSON parsing error in row starting at position 0: Start of array encountered without start of object. File: gs://airflow_bucket_name/transformed_data/mongo_data.json
[2024-11-10T14:55:50.912+0000] {local_task_job_runner.py:266} INFO - Task exited with return code 1
[2024-11-10T14:55:50.947+0000] {taskinstance.py:3895} INFO - 0 downstream tasks scheduled from follow-on schedule check
[2024-11-10T14:55:50.950+0000] {local_task_job_runner.py:245} INFO - ::endgroup::
