[2024-11-09T16:27:56.071+0000] {local_task_job_runner.py:123} INFO - ::group::Pre task execution logs
[2024-11-09T16:27:56.188+0000] {taskinstance.py:2613} INFO - Dependencies all met for dep_context=non-requeueable deps ti=<TaskInstance: mongodb_atlas_fetch_load_data.fetch_data manual__2024-11-09T16:27:49.410019+00:00 [queued]>
[2024-11-09T16:27:56.219+0000] {taskinstance.py:2613} INFO - Dependencies all met for dep_context=requeueable deps ti=<TaskInstance: mongodb_atlas_fetch_load_data.fetch_data manual__2024-11-09T16:27:49.410019+00:00 [queued]>
[2024-11-09T16:27:56.219+0000] {taskinstance.py:2866} INFO - Starting attempt 1 of 1
[2024-11-09T16:27:56.259+0000] {taskinstance.py:2889} INFO - Executing <Task(PythonOperator): fetch_data> on 2024-11-09 16:27:49.410019+00:00
[2024-11-09T16:27:56.285+0000] {warnings.py:112} WARNING - /home/***/.local/lib/python3.12/site-packages/***/task/task_runner/standard_task_runner.py:70: DeprecationWarning: This process (pid=295) is multi-threaded, use of fork() may lead to deadlocks in the child.
  pid = os.fork()

[2024-11-09T16:27:56.290+0000] {standard_task_runner.py:72} INFO - Started process 297 to run task
[2024-11-09T16:27:56.288+0000] {standard_task_runner.py:104} INFO - Running: ['***', 'tasks', 'run', 'mongodb_atlas_fetch_load_data', 'fetch_data', 'manual__2024-11-09T16:27:49.410019+00:00', '--job-id', '62', '--raw', '--subdir', 'DAGS_FOLDER/et_pipeline.py', '--cfg-path', '/tmp/tmpm6kguej2']
[2024-11-09T16:27:56.291+0000] {standard_task_runner.py:105} INFO - Job 62: Subtask fetch_data
[2024-11-09T16:27:56.430+0000] {task_command.py:467} INFO - Running <TaskInstance: mongodb_atlas_fetch_load_data.fetch_data manual__2024-11-09T16:27:49.410019+00:00 [running]> on host 9c1a8e215aa5
[2024-11-09T16:27:57.434+0000] {taskinstance.py:3132} INFO - Exporting env vars: AIRFLOW_CTX_DAG_OWNER='***' AIRFLOW_CTX_DAG_ID='mongodb_atlas_fetch_load_data' AIRFLOW_CTX_TASK_ID='fetch_data' AIRFLOW_CTX_EXECUTION_DATE='2024-11-09T16:27:49.410019+00:00' AIRFLOW_CTX_TRY_NUMBER='1' AIRFLOW_CTX_DAG_RUN_ID='manual__2024-11-09T16:27:49.410019+00:00'
[2024-11-09T16:27:57.438+0000] {logging_mixin.py:190} INFO - Task instance is in running state
[2024-11-09T16:27:57.444+0000] {logging_mixin.py:190} INFO -  Previous state of the Task instance: queued
[2024-11-09T16:27:57.452+0000] {logging_mixin.py:190} INFO - Current task name:fetch_data state:running start_date:2024-11-09 16:27:56.189428+00:00
[2024-11-09T16:27:57.453+0000] {logging_mixin.py:190} INFO - Dag name:mongodb_atlas_fetch_load_data and current dag run status:running
[2024-11-09T16:27:57.454+0000] {taskinstance.py:731} INFO - ::endgroup::
[2024-11-09T16:27:57.455+0000] {logging_mixin.py:190} INFO - Fetching data from MongoDB...
[2024-11-09T16:27:57.543+0000] {base.py:84} INFO - Retrieving connection 'mongo_default'
[2024-11-09T16:39:14.392+0000] {taskinstance.py:3311} ERROR - Task failed with exception
Traceback (most recent call last):
  File "/home/airflow/.local/lib/python3.12/site-packages/pymongo/synchronous/pool.py", line 590, in receive_message
    return receive_message(self, request_id, self.max_message_size)
           ^^^^^^^^^^^^^^^^^^^^^^^^^^^^^^^^^^^^^^^^^^^^^^^^^^^^^^^^
  File "/home/airflow/.local/lib/python3.12/site-packages/pymongo/synchronous/network.py", line 340, in receive_message
    data = _receive_data_on_socket(conn, length - 16, deadline)
           ^^^^^^^^^^^^^^^^^^^^^^^^^^^^^^^^^^^^^^^^^^^^^^^^^^^^
  File "/home/airflow/.local/lib/python3.12/site-packages/pymongo/synchronous/network.py", line 404, in _receive_data_on_socket
    raise OSError("connection closed")
OSError: connection closed

The above exception was the direct cause of the following exception:

Traceback (most recent call last):
  File "/home/airflow/.local/lib/python3.12/site-packages/airflow/models/taskinstance.py", line 767, in _execute_task
    result = _execute_callable(context=context, **execute_callable_kwargs)
             ^^^^^^^^^^^^^^^^^^^^^^^^^^^^^^^^^^^^^^^^^^^^^^^^^^^^^^^^^^^^^
  File "/home/airflow/.local/lib/python3.12/site-packages/airflow/models/taskinstance.py", line 733, in _execute_callable
    return ExecutionCallableRunner(
           ^^^^^^^^^^^^^^^^^^^^^^^^
  File "/home/airflow/.local/lib/python3.12/site-packages/airflow/utils/operator_helpers.py", line 252, in run
    return self.func(*args, **kwargs)
           ^^^^^^^^^^^^^^^^^^^^^^^^^^
  File "/home/airflow/.local/lib/python3.12/site-packages/airflow/models/baseoperator.py", line 417, in wrapper
    return func(self, *args, **kwargs)
           ^^^^^^^^^^^^^^^^^^^^^^^^^^^
  File "/home/airflow/.local/lib/python3.12/site-packages/airflow/operators/python.py", line 238, in execute
    return_value = self.execute_callable()
                   ^^^^^^^^^^^^^^^^^^^^^^^
  File "/home/airflow/.local/lib/python3.12/site-packages/airflow/operators/python.py", line 256, in execute_callable
    return runner.run(*self.op_args, **self.op_kwargs)
           ^^^^^^^^^^^^^^^^^^^^^^^^^^^^^^^^^^^^^^^^^^^
  File "/home/airflow/.local/lib/python3.12/site-packages/airflow/utils/operator_helpers.py", line 252, in run
    return self.func(*args, **kwargs)
           ^^^^^^^^^^^^^^^^^^^^^^^^^^
  File "/opt/airflow/dags/et_pipeline.py", line 26, in fetch_data_from_mongo
    data_list = list(data)
                ^^^^^^^^^^
  File "/home/airflow/.local/lib/python3.12/site-packages/pymongo/synchronous/cursor.py", line 1281, in __next__
    return self.next()
           ^^^^^^^^^^^
  File "/home/airflow/.local/lib/python3.12/site-packages/pymongo/synchronous/cursor.py", line 1257, in next
    if len(self._data) or self._refresh():
                          ^^^^^^^^^^^^^^^
  File "/home/airflow/.local/lib/python3.12/site-packages/pymongo/synchronous/cursor.py", line 1228, in _refresh
    self._send_message(g)
  File "/home/airflow/.local/lib/python3.12/site-packages/pymongo/synchronous/cursor.py", line 1100, in _send_message
    response = client._run_operation(
               ^^^^^^^^^^^^^^^^^^^^^^
  File "/home/airflow/.local/lib/python3.12/site-packages/pymongo/_csot.py", line 119, in csot_wrapper
    return func(self, *args, **kwargs)
           ^^^^^^^^^^^^^^^^^^^^^^^^^^^
  File "/home/airflow/.local/lib/python3.12/site-packages/pymongo/synchronous/mongo_client.py", line 1754, in _run_operation
    return self._retryable_read(
           ^^^^^^^^^^^^^^^^^^^^^
  File "/home/airflow/.local/lib/python3.12/site-packages/pymongo/synchronous/mongo_client.py", line 1863, in _retryable_read
    return self._retry_internal(
           ^^^^^^^^^^^^^^^^^^^^^
  File "/home/airflow/.local/lib/python3.12/site-packages/pymongo/_csot.py", line 119, in csot_wrapper
    return func(self, *args, **kwargs)
           ^^^^^^^^^^^^^^^^^^^^^^^^^^^
  File "/home/airflow/.local/lib/python3.12/site-packages/pymongo/synchronous/mongo_client.py", line 1830, in _retry_internal
    ).run()
      ^^^^^
  File "/home/airflow/.local/lib/python3.12/site-packages/pymongo/synchronous/mongo_client.py", line 2554, in run
    return self._read() if self._is_read else self._write()
           ^^^^^^^^^^^^
  File "/home/airflow/.local/lib/python3.12/site-packages/pymongo/synchronous/mongo_client.py", line 2697, in _read
    return self._func(self._session, self._server, conn, read_pref)  # type: ignore
           ^^^^^^^^^^^^^^^^^^^^^^^^^^^^^^^^^^^^^^^^^^^^^^^^^^^^^^^^
  File "/home/airflow/.local/lib/python3.12/site-packages/pymongo/synchronous/mongo_client.py", line 1745, in _cmd
    return server.run_operation(
           ^^^^^^^^^^^^^^^^^^^^^
  File "/home/airflow/.local/lib/python3.12/site-packages/pymongo/synchronous/helpers.py", line 45, in inner
    return func(*args, **kwargs)
           ^^^^^^^^^^^^^^^^^^^^^
  File "/home/airflow/.local/lib/python3.12/site-packages/pymongo/synchronous/server.py", line 208, in run_operation
    reply = conn.receive_message(request_id)
            ^^^^^^^^^^^^^^^^^^^^^^^^^^^^^^^^
  File "/home/airflow/.local/lib/python3.12/site-packages/pymongo/synchronous/pool.py", line 592, in receive_message
    self._raise_connection_failure(error)
  File "/home/airflow/.local/lib/python3.12/site-packages/pymongo/synchronous/pool.py", line 763, in _raise_connection_failure
    _raise_connection_failure(self.address, error, timeout_details=details)
  File "/home/airflow/.local/lib/python3.12/site-packages/pymongo/synchronous/pool.py", line 208, in _raise_connection_failure
    raise AutoReconnect(msg) from error
pymongo.errors.AutoReconnect: ac-ibpsuue-shard-00-01.hgzqemt.mongodb.net:27017: connection closed (configured timeouts: connectTimeoutMS: 20000.0ms)
[2024-11-09T16:39:14.439+0000] {logging_mixin.py:190} INFO - Task instance in failure state
[2024-11-09T16:39:14.442+0000] {logging_mixin.py:190} INFO - Task start:2024-11-09 16:27:56.189428+00:00 end:2024-11-09 16:39:14.437938+00:00 duration:678.24851
[2024-11-09T16:39:14.444+0000] {logging_mixin.py:190} INFO - Task:<Task(PythonOperator): fetch_data> dag:<DAG: mongodb_atlas_fetch_load_data> dagrun:<DagRun mongodb_atlas_fetch_load_data @ 2024-11-09 16:27:49.410019+00:00: manual__2024-11-09T16:27:49.410019+00:00, state:running, queued_at: 2024-11-09 16:27:49.425258+00:00. externally triggered: True>
[2024-11-09T16:39:14.445+0000] {logging_mixin.py:190} INFO - Failure caused by ac-ibpsuue-shard-00-01.hgzqemt.mongodb.net:27017: connection closed (configured timeouts: connectTimeoutMS: 20000.0ms)
[2024-11-09T16:39:14.446+0000] {taskinstance.py:1225} INFO - Marking task as FAILED. dag_id=mongodb_atlas_fetch_load_data, task_id=fetch_data, run_id=manual__2024-11-09T16:27:49.410019+00:00, execution_date=20241109T162749, start_date=20241109T162756, end_date=20241109T163914
[2024-11-09T16:39:14.478+0000] {taskinstance.py:340} INFO - ::group::Post task execution logs
[2024-11-09T16:39:14.479+0000] {standard_task_runner.py:124} ERROR - Failed to execute job 62 for task fetch_data (ac-ibpsuue-shard-00-01.hgzqemt.mongodb.net:27017: connection closed (configured timeouts: connectTimeoutMS: 20000.0ms); 297)
Traceback (most recent call last):
  File "/home/airflow/.local/lib/python3.12/site-packages/pymongo/synchronous/pool.py", line 590, in receive_message
    return receive_message(self, request_id, self.max_message_size)
           ^^^^^^^^^^^^^^^^^^^^^^^^^^^^^^^^^^^^^^^^^^^^^^^^^^^^^^^^
  File "/home/airflow/.local/lib/python3.12/site-packages/pymongo/synchronous/network.py", line 340, in receive_message
    data = _receive_data_on_socket(conn, length - 16, deadline)
           ^^^^^^^^^^^^^^^^^^^^^^^^^^^^^^^^^^^^^^^^^^^^^^^^^^^^
  File "/home/airflow/.local/lib/python3.12/site-packages/pymongo/synchronous/network.py", line 404, in _receive_data_on_socket
    raise OSError("connection closed")
OSError: connection closed

The above exception was the direct cause of the following exception:

Traceback (most recent call last):
  File "/home/airflow/.local/lib/python3.12/site-packages/airflow/task/task_runner/standard_task_runner.py", line 117, in _start_by_fork
    ret = args.func(args, dag=self.dag)
          ^^^^^^^^^^^^^^^^^^^^^^^^^^^^^
  File "/home/airflow/.local/lib/python3.12/site-packages/airflow/cli/cli_config.py", line 49, in command
    return func(*args, **kwargs)
           ^^^^^^^^^^^^^^^^^^^^^
  File "/home/airflow/.local/lib/python3.12/site-packages/airflow/utils/cli.py", line 116, in wrapper
    return f(*args, **kwargs)
           ^^^^^^^^^^^^^^^^^^
  File "/home/airflow/.local/lib/python3.12/site-packages/airflow/cli/commands/task_command.py", line 483, in task_run
    task_return_code = _run_task_by_selected_method(args, _dag, ti)
                       ^^^^^^^^^^^^^^^^^^^^^^^^^^^^^^^^^^^^^^^^^^^^
  File "/home/airflow/.local/lib/python3.12/site-packages/airflow/cli/commands/task_command.py", line 256, in _run_task_by_selected_method
    return _run_raw_task(args, ti)
           ^^^^^^^^^^^^^^^^^^^^^^^
  File "/home/airflow/.local/lib/python3.12/site-packages/airflow/cli/commands/task_command.py", line 341, in _run_raw_task
    return ti._run_raw_task(
           ^^^^^^^^^^^^^^^^^
  File "/home/airflow/.local/lib/python3.12/site-packages/airflow/utils/session.py", line 97, in wrapper
    return func(*args, session=session, **kwargs)
           ^^^^^^^^^^^^^^^^^^^^^^^^^^^^^^^^^^^^^^
  File "/home/airflow/.local/lib/python3.12/site-packages/airflow/models/taskinstance.py", line 3005, in _run_raw_task
    return _run_raw_task(
           ^^^^^^^^^^^^^^
  File "/home/airflow/.local/lib/python3.12/site-packages/airflow/models/taskinstance.py", line 273, in _run_raw_task
    TaskInstance._execute_task_with_callbacks(
  File "/home/airflow/.local/lib/python3.12/site-packages/airflow/models/taskinstance.py", line 3159, in _execute_task_with_callbacks
    result = self._execute_task(context, task_orig)
             ^^^^^^^^^^^^^^^^^^^^^^^^^^^^^^^^^^^^^^
  File "/home/airflow/.local/lib/python3.12/site-packages/airflow/models/taskinstance.py", line 3183, in _execute_task
    return _execute_task(self, context, task_orig)
           ^^^^^^^^^^^^^^^^^^^^^^^^^^^^^^^^^^^^^^^
  File "/home/airflow/.local/lib/python3.12/site-packages/airflow/models/taskinstance.py", line 767, in _execute_task
    result = _execute_callable(context=context, **execute_callable_kwargs)
             ^^^^^^^^^^^^^^^^^^^^^^^^^^^^^^^^^^^^^^^^^^^^^^^^^^^^^^^^^^^^^
  File "/home/airflow/.local/lib/python3.12/site-packages/airflow/models/taskinstance.py", line 733, in _execute_callable
    return ExecutionCallableRunner(
           ^^^^^^^^^^^^^^^^^^^^^^^^
  File "/home/airflow/.local/lib/python3.12/site-packages/airflow/utils/operator_helpers.py", line 252, in run
    return self.func(*args, **kwargs)
           ^^^^^^^^^^^^^^^^^^^^^^^^^^
  File "/home/airflow/.local/lib/python3.12/site-packages/airflow/models/baseoperator.py", line 417, in wrapper
    return func(self, *args, **kwargs)
           ^^^^^^^^^^^^^^^^^^^^^^^^^^^
  File "/home/airflow/.local/lib/python3.12/site-packages/airflow/operators/python.py", line 238, in execute
    return_value = self.execute_callable()
                   ^^^^^^^^^^^^^^^^^^^^^^^
  File "/home/airflow/.local/lib/python3.12/site-packages/airflow/operators/python.py", line 256, in execute_callable
    return runner.run(*self.op_args, **self.op_kwargs)
           ^^^^^^^^^^^^^^^^^^^^^^^^^^^^^^^^^^^^^^^^^^^
  File "/home/airflow/.local/lib/python3.12/site-packages/airflow/utils/operator_helpers.py", line 252, in run
    return self.func(*args, **kwargs)
           ^^^^^^^^^^^^^^^^^^^^^^^^^^
  File "/opt/airflow/dags/et_pipeline.py", line 26, in fetch_data_from_mongo
    data_list = list(data)
                ^^^^^^^^^^
  File "/home/airflow/.local/lib/python3.12/site-packages/pymongo/synchronous/cursor.py", line 1281, in __next__
    return self.next()
           ^^^^^^^^^^^
  File "/home/airflow/.local/lib/python3.12/site-packages/pymongo/synchronous/cursor.py", line 1257, in next
    if len(self._data) or self._refresh():
                          ^^^^^^^^^^^^^^^
  File "/home/airflow/.local/lib/python3.12/site-packages/pymongo/synchronous/cursor.py", line 1228, in _refresh
    self._send_message(g)
  File "/home/airflow/.local/lib/python3.12/site-packages/pymongo/synchronous/cursor.py", line 1100, in _send_message
    response = client._run_operation(
               ^^^^^^^^^^^^^^^^^^^^^^
  File "/home/airflow/.local/lib/python3.12/site-packages/pymongo/_csot.py", line 119, in csot_wrapper
    return func(self, *args, **kwargs)
           ^^^^^^^^^^^^^^^^^^^^^^^^^^^
  File "/home/airflow/.local/lib/python3.12/site-packages/pymongo/synchronous/mongo_client.py", line 1754, in _run_operation
    return self._retryable_read(
           ^^^^^^^^^^^^^^^^^^^^^
  File "/home/airflow/.local/lib/python3.12/site-packages/pymongo/synchronous/mongo_client.py", line 1863, in _retryable_read
    return self._retry_internal(
           ^^^^^^^^^^^^^^^^^^^^^
  File "/home/airflow/.local/lib/python3.12/site-packages/pymongo/_csot.py", line 119, in csot_wrapper
    return func(self, *args, **kwargs)
           ^^^^^^^^^^^^^^^^^^^^^^^^^^^
  File "/home/airflow/.local/lib/python3.12/site-packages/pymongo/synchronous/mongo_client.py", line 1830, in _retry_internal
    ).run()
      ^^^^^
  File "/home/airflow/.local/lib/python3.12/site-packages/pymongo/synchronous/mongo_client.py", line 2554, in run
    return self._read() if self._is_read else self._write()
           ^^^^^^^^^^^^
  File "/home/airflow/.local/lib/python3.12/site-packages/pymongo/synchronous/mongo_client.py", line 2697, in _read
    return self._func(self._session, self._server, conn, read_pref)  # type: ignore
           ^^^^^^^^^^^^^^^^^^^^^^^^^^^^^^^^^^^^^^^^^^^^^^^^^^^^^^^^
  File "/home/airflow/.local/lib/python3.12/site-packages/pymongo/synchronous/mongo_client.py", line 1745, in _cmd
    return server.run_operation(
           ^^^^^^^^^^^^^^^^^^^^^
  File "/home/airflow/.local/lib/python3.12/site-packages/pymongo/synchronous/helpers.py", line 45, in inner
    return func(*args, **kwargs)
           ^^^^^^^^^^^^^^^^^^^^^
  File "/home/airflow/.local/lib/python3.12/site-packages/pymongo/synchronous/server.py", line 208, in run_operation
    reply = conn.receive_message(request_id)
            ^^^^^^^^^^^^^^^^^^^^^^^^^^^^^^^^
  File "/home/airflow/.local/lib/python3.12/site-packages/pymongo/synchronous/pool.py", line 592, in receive_message
    self._raise_connection_failure(error)
  File "/home/airflow/.local/lib/python3.12/site-packages/pymongo/synchronous/pool.py", line 763, in _raise_connection_failure
    _raise_connection_failure(self.address, error, timeout_details=details)
  File "/home/airflow/.local/lib/python3.12/site-packages/pymongo/synchronous/pool.py", line 208, in _raise_connection_failure
    raise AutoReconnect(msg) from error
pymongo.errors.AutoReconnect: ac-ibpsuue-shard-00-01.hgzqemt.mongodb.net:27017: connection closed (configured timeouts: connectTimeoutMS: 20000.0ms)
[2024-11-09T16:39:14.559+0000] {local_task_job_runner.py:266} INFO - Task exited with return code 1
[2024-11-09T16:39:14.598+0000] {taskinstance.py:3895} INFO - 0 downstream tasks scheduled from follow-on schedule check
[2024-11-09T16:39:14.602+0000] {local_task_job_runner.py:245} INFO - ::endgroup::
