[2024-11-08T16:58:28.907+0000] {local_task_job_runner.py:123} INFO - ::group::Pre task execution logs
[2024-11-08T16:58:29.014+0000] {taskinstance.py:2613} INFO - Dependencies all met for dep_context=non-requeueable deps ti=<TaskInstance: etl_articles_pipeline.extract_task scheduled__2024-11-01T00:00:00+00:00 [queued]>
[2024-11-08T16:58:29.055+0000] {taskinstance.py:2613} INFO - Dependencies all met for dep_context=requeueable deps ti=<TaskInstance: etl_articles_pipeline.extract_task scheduled__2024-11-01T00:00:00+00:00 [queued]>
[2024-11-08T16:58:29.057+0000] {taskinstance.py:2866} INFO - Starting attempt 1 of 2
[2024-11-08T16:58:29.118+0000] {taskinstance.py:2889} INFO - Executing <Task(PythonOperator): extract_task> on 2024-11-01 00:00:00+00:00
[2024-11-08T16:58:29.157+0000] {warnings.py:112} WARNING - /home/***/.local/lib/python3.12/site-packages/***/task/task_runner/standard_task_runner.py:70: DeprecationWarning: This process (pid=596) is multi-threaded, use of fork() may lead to deadlocks in the child.
  pid = os.fork()

[2024-11-08T16:58:29.164+0000] {standard_task_runner.py:72} INFO - Started process 614 to run task
[2024-11-08T16:58:29.167+0000] {standard_task_runner.py:104} INFO - Running: ['***', 'tasks', 'run', 'etl_articles_pipeline', 'extract_task', 'scheduled__2024-11-01T00:00:00+00:00', '--job-id', '14', '--raw', '--subdir', 'DAGS_FOLDER/dag2.py', '--cfg-path', '/tmp/tmp76wup4s8']
[2024-11-08T16:58:29.171+0000] {standard_task_runner.py:105} INFO - Job 14: Subtask extract_task
[2024-11-08T16:58:29.552+0000] {task_command.py:467} INFO - Running <TaskInstance: etl_articles_pipeline.extract_task scheduled__2024-11-01T00:00:00+00:00 [running]> on host 456dfefbad51
[2024-11-08T16:58:32.410+0000] {taskinstance.py:3132} INFO - Exporting env vars: AIRFLOW_CTX_DAG_OWNER='***' AIRFLOW_CTX_DAG_ID='etl_articles_pipeline' AIRFLOW_CTX_TASK_ID='extract_task' AIRFLOW_CTX_EXECUTION_DATE='2024-11-01T00:00:00+00:00' AIRFLOW_CTX_TRY_NUMBER='1' AIRFLOW_CTX_DAG_RUN_ID='scheduled__2024-11-01T00:00:00+00:00'
[2024-11-08T16:58:32.415+0000] {logging_mixin.py:190} INFO - Task instance is in running state
[2024-11-08T16:58:32.417+0000] {logging_mixin.py:190} INFO -  Previous state of the Task instance: queued
[2024-11-08T16:58:32.425+0000] {logging_mixin.py:190} INFO - Current task name:extract_task state:running start_date:2024-11-08 16:58:29.017312+00:00
[2024-11-08T16:58:32.431+0000] {logging_mixin.py:190} INFO - Dag name:etl_articles_pipeline and current dag run status:running
[2024-11-08T16:58:32.433+0000] {taskinstance.py:731} INFO - ::endgroup::
[2024-11-08T16:58:32.854+0000] {taskinstance.py:3311} ERROR - Task failed with exception
Traceback (most recent call last):
  File "/home/airflow/.local/lib/python3.12/site-packages/airflow/models/taskinstance.py", line 767, in _execute_task
    result = _execute_callable(context=context, **execute_callable_kwargs)
             ^^^^^^^^^^^^^^^^^^^^^^^^^^^^^^^^^^^^^^^^^^^^^^^^^^^^^^^^^^^^^
  File "/home/airflow/.local/lib/python3.12/site-packages/airflow/models/taskinstance.py", line 733, in _execute_callable
    return ExecutionCallableRunner(
           ^^^^^^^^^^^^^^^^^^^^^^^^
  File "/home/airflow/.local/lib/python3.12/site-packages/airflow/utils/operator_helpers.py", line 252, in run
    return self.func(*args, **kwargs)
           ^^^^^^^^^^^^^^^^^^^^^^^^^^
  File "/home/airflow/.local/lib/python3.12/site-packages/airflow/models/baseoperator.py", line 417, in wrapper
    return func(self, *args, **kwargs)
           ^^^^^^^^^^^^^^^^^^^^^^^^^^^
  File "/home/airflow/.local/lib/python3.12/site-packages/airflow/operators/python.py", line 238, in execute
    return_value = self.execute_callable()
                   ^^^^^^^^^^^^^^^^^^^^^^^
  File "/home/airflow/.local/lib/python3.12/site-packages/airflow/operators/python.py", line 256, in execute_callable
    return runner.run(*self.op_args, **self.op_kwargs)
           ^^^^^^^^^^^^^^^^^^^^^^^^^^^^^^^^^^^^^^^^^^^
  File "/home/airflow/.local/lib/python3.12/site-packages/airflow/utils/operator_helpers.py", line 252, in run
    return self.func(*args, **kwargs)
           ^^^^^^^^^^^^^^^^^^^^^^^^^^
  File "/opt/airflow/dags/dag2.py", line 30, in extract_articles
    raise Exception('Erreur lors de la récupération des données')
Exception: Erreur lors de la récupération des données
[2024-11-08T16:58:32.972+0000] {logging_mixin.py:190} INFO - Task instance in failure state
[2024-11-08T16:58:32.973+0000] {logging_mixin.py:190} INFO - Task start:2024-11-08 16:58:29.017312+00:00 end:2024-11-08 16:58:32.971606+00:00 duration:3.954294
[2024-11-08T16:58:32.974+0000] {logging_mixin.py:190} INFO - Task:<Task(PythonOperator): extract_task> dag:<DAG: etl_articles_pipeline> dagrun:<DagRun etl_articles_pipeline @ 2024-11-01 00:00:00+00:00: scheduled__2024-11-01T00:00:00+00:00, state:running, queued_at: 2024-11-08 16:58:10.000175+00:00. externally triggered: False>
[2024-11-08T16:58:32.975+0000] {logging_mixin.py:190} INFO - Failure caused by Erreur lors de la récupération des données
[2024-11-08T16:58:32.976+0000] {taskinstance.py:1225} INFO - Marking task as UP_FOR_RETRY. dag_id=etl_articles_pipeline, task_id=extract_task, run_id=scheduled__2024-11-01T00:00:00+00:00, execution_date=20241101T000000, start_date=20241108T165829, end_date=20241108T165832
[2024-11-08T16:58:33.219+0000] {taskinstance.py:340} INFO - ::group::Post task execution logs
[2024-11-08T16:58:33.220+0000] {standard_task_runner.py:124} ERROR - Failed to execute job 14 for task extract_task (Erreur lors de la récupération des données; 614)
Traceback (most recent call last):
  File "/home/airflow/.local/lib/python3.12/site-packages/airflow/task/task_runner/standard_task_runner.py", line 117, in _start_by_fork
    ret = args.func(args, dag=self.dag)
          ^^^^^^^^^^^^^^^^^^^^^^^^^^^^^
  File "/home/airflow/.local/lib/python3.12/site-packages/airflow/cli/cli_config.py", line 49, in command
    return func(*args, **kwargs)
           ^^^^^^^^^^^^^^^^^^^^^
  File "/home/airflow/.local/lib/python3.12/site-packages/airflow/utils/cli.py", line 116, in wrapper
    return f(*args, **kwargs)
           ^^^^^^^^^^^^^^^^^^
  File "/home/airflow/.local/lib/python3.12/site-packages/airflow/cli/commands/task_command.py", line 483, in task_run
    task_return_code = _run_task_by_selected_method(args, _dag, ti)
                       ^^^^^^^^^^^^^^^^^^^^^^^^^^^^^^^^^^^^^^^^^^^^
  File "/home/airflow/.local/lib/python3.12/site-packages/airflow/cli/commands/task_command.py", line 256, in _run_task_by_selected_method
    return _run_raw_task(args, ti)
           ^^^^^^^^^^^^^^^^^^^^^^^
  File "/home/airflow/.local/lib/python3.12/site-packages/airflow/cli/commands/task_command.py", line 341, in _run_raw_task
    return ti._run_raw_task(
           ^^^^^^^^^^^^^^^^^
  File "/home/airflow/.local/lib/python3.12/site-packages/airflow/utils/session.py", line 97, in wrapper
    return func(*args, session=session, **kwargs)
           ^^^^^^^^^^^^^^^^^^^^^^^^^^^^^^^^^^^^^^
  File "/home/airflow/.local/lib/python3.12/site-packages/airflow/models/taskinstance.py", line 3005, in _run_raw_task
    return _run_raw_task(
           ^^^^^^^^^^^^^^
  File "/home/airflow/.local/lib/python3.12/site-packages/airflow/models/taskinstance.py", line 273, in _run_raw_task
    TaskInstance._execute_task_with_callbacks(
  File "/home/airflow/.local/lib/python3.12/site-packages/airflow/models/taskinstance.py", line 3159, in _execute_task_with_callbacks
    result = self._execute_task(context, task_orig)
             ^^^^^^^^^^^^^^^^^^^^^^^^^^^^^^^^^^^^^^
  File "/home/airflow/.local/lib/python3.12/site-packages/airflow/models/taskinstance.py", line 3183, in _execute_task
    return _execute_task(self, context, task_orig)
           ^^^^^^^^^^^^^^^^^^^^^^^^^^^^^^^^^^^^^^^
  File "/home/airflow/.local/lib/python3.12/site-packages/airflow/models/taskinstance.py", line 767, in _execute_task
    result = _execute_callable(context=context, **execute_callable_kwargs)
             ^^^^^^^^^^^^^^^^^^^^^^^^^^^^^^^^^^^^^^^^^^^^^^^^^^^^^^^^^^^^^
  File "/home/airflow/.local/lib/python3.12/site-packages/airflow/models/taskinstance.py", line 733, in _execute_callable
    return ExecutionCallableRunner(
           ^^^^^^^^^^^^^^^^^^^^^^^^
  File "/home/airflow/.local/lib/python3.12/site-packages/airflow/utils/operator_helpers.py", line 252, in run
    return self.func(*args, **kwargs)
           ^^^^^^^^^^^^^^^^^^^^^^^^^^
  File "/home/airflow/.local/lib/python3.12/site-packages/airflow/models/baseoperator.py", line 417, in wrapper
    return func(self, *args, **kwargs)
           ^^^^^^^^^^^^^^^^^^^^^^^^^^^
  File "/home/airflow/.local/lib/python3.12/site-packages/airflow/operators/python.py", line 238, in execute
    return_value = self.execute_callable()
                   ^^^^^^^^^^^^^^^^^^^^^^^
  File "/home/airflow/.local/lib/python3.12/site-packages/airflow/operators/python.py", line 256, in execute_callable
    return runner.run(*self.op_args, **self.op_kwargs)
           ^^^^^^^^^^^^^^^^^^^^^^^^^^^^^^^^^^^^^^^^^^^
  File "/home/airflow/.local/lib/python3.12/site-packages/airflow/utils/operator_helpers.py", line 252, in run
    return self.func(*args, **kwargs)
           ^^^^^^^^^^^^^^^^^^^^^^^^^^
  File "/opt/airflow/dags/dag2.py", line 30, in extract_articles
    raise Exception('Erreur lors de la récupération des données')
Exception: Erreur lors de la récupération des données
[2024-11-08T16:58:33.476+0000] {local_task_job_runner.py:266} INFO - Task exited with return code 1
[2024-11-08T16:58:33.785+0000] {taskinstance.py:3895} INFO - 0 downstream tasks scheduled from follow-on schedule check
[2024-11-08T16:58:33.792+0000] {local_task_job_runner.py:245} INFO - ::endgroup::
