[2024-11-08T13:37:55.588+0000] {local_task_job_runner.py:123} INFO - ::group::Pre task execution logs
[2024-11-08T13:37:55.616+0000] {taskinstance.py:2613} INFO - Dependencies all met for dep_context=non-requeueable deps ti=<TaskInstance: create_postgres_table_dag.test_connection manual__2024-11-08T13:37:44.123879+00:00 [queued]>
[2024-11-08T13:37:55.628+0000] {taskinstance.py:2613} INFO - Dependencies all met for dep_context=requeueable deps ti=<TaskInstance: create_postgres_table_dag.test_connection manual__2024-11-08T13:37:44.123879+00:00 [queued]>
[2024-11-08T13:37:55.629+0000] {taskinstance.py:2866} INFO - Starting attempt 1 of 2
[2024-11-08T13:37:55.855+0000] {taskinstance.py:2889} INFO - Executing <Task(PostgresOperator): test_connection> on 2024-11-08 13:37:44.123879+00:00
[2024-11-08T13:37:55.874+0000] {warnings.py:112} WARNING - /home/***/.local/lib/python3.12/site-packages/***/task/task_runner/standard_task_runner.py:70: DeprecationWarning: This process (pid=271) is multi-threaded, use of fork() may lead to deadlocks in the child.
  pid = os.fork()

[2024-11-08T13:37:55.877+0000] {standard_task_runner.py:72} INFO - Started process 273 to run task
[2024-11-08T13:37:55.879+0000] {standard_task_runner.py:104} INFO - Running: ['***', 'tasks', 'run', 'create_postgres_table_dag', 'test_connection', 'manual__2024-11-08T13:37:44.123879+00:00', '--job-id', '8', '--raw', '--subdir', 'DAGS_FOLDER/dag.py', '--cfg-path', '/tmp/tmpbrogku_r']
[2024-11-08T13:37:55.883+0000] {standard_task_runner.py:105} INFO - Job 8: Subtask test_connection
[2024-11-08T13:37:56.076+0000] {task_command.py:467} INFO - Running <TaskInstance: create_postgres_table_dag.test_connection manual__2024-11-08T13:37:44.123879+00:00 [running]> on host 456dfefbad51
[2024-11-08T13:37:56.406+0000] {taskinstance.py:3132} INFO - Exporting env vars: AIRFLOW_CTX_DAG_OWNER='***' AIRFLOW_CTX_DAG_ID='create_postgres_table_dag' AIRFLOW_CTX_TASK_ID='test_connection' AIRFLOW_CTX_EXECUTION_DATE='2024-11-08T13:37:44.123879+00:00' AIRFLOW_CTX_TRY_NUMBER='1' AIRFLOW_CTX_DAG_RUN_ID='manual__2024-11-08T13:37:44.123879+00:00'
[2024-11-08T13:37:56.408+0000] {logging_mixin.py:190} INFO - Task instance is in running state
[2024-11-08T13:37:56.408+0000] {logging_mixin.py:190} INFO -  Previous state of the Task instance: queued
[2024-11-08T13:37:56.408+0000] {logging_mixin.py:190} INFO - Current task name:test_connection state:running start_date:2024-11-08 13:37:55.617329+00:00
[2024-11-08T13:37:56.409+0000] {logging_mixin.py:190} INFO - Dag name:create_postgres_table_dag and current dag run status:running
[2024-11-08T13:37:56.409+0000] {taskinstance.py:731} INFO - ::endgroup::
[2024-11-08T13:37:56.410+0000] {sql.py:278} INFO - Executing: SELECT 1;
[2024-11-08T13:37:56.425+0000] {base.py:84} INFO - Retrieving connection 'acticls_connection'
[2024-11-08T13:37:56.452+0000] {base.py:84} INFO - Retrieving connection 'acticls_connection'
[2024-11-08T13:37:56.457+0000] {taskinstance.py:3311} ERROR - Task failed with exception
Traceback (most recent call last):
  File "/home/airflow/.local/lib/python3.12/site-packages/airflow/models/taskinstance.py", line 767, in _execute_task
    result = _execute_callable(context=context, **execute_callable_kwargs)
             ^^^^^^^^^^^^^^^^^^^^^^^^^^^^^^^^^^^^^^^^^^^^^^^^^^^^^^^^^^^^^
  File "/home/airflow/.local/lib/python3.12/site-packages/airflow/models/taskinstance.py", line 733, in _execute_callable
    return ExecutionCallableRunner(
           ^^^^^^^^^^^^^^^^^^^^^^^^
  File "/home/airflow/.local/lib/python3.12/site-packages/airflow/utils/operator_helpers.py", line 252, in run
    return self.func(*args, **kwargs)
           ^^^^^^^^^^^^^^^^^^^^^^^^^^
  File "/home/airflow/.local/lib/python3.12/site-packages/airflow/models/baseoperator.py", line 417, in wrapper
    return func(self, *args, **kwargs)
           ^^^^^^^^^^^^^^^^^^^^^^^^^^^
  File "/home/airflow/.local/lib/python3.12/site-packages/airflow/providers/common/sql/operators/sql.py", line 284, in execute
    output = hook.run(
             ^^^^^^^^^
  File "/home/airflow/.local/lib/python3.12/site-packages/airflow/providers/common/sql/hooks/sql.py", line 485, in run
    with self._create_autocommit_connection(autocommit) as conn:
         ^^^^^^^^^^^^^^^^^^^^^^^^^^^^^^^^^^^^^^^^^^^^^^
  File "/usr/local/lib/python3.12/contextlib.py", line 137, in __enter__
    return next(self.gen)
           ^^^^^^^^^^^^^^
  File "/home/airflow/.local/lib/python3.12/site-packages/airflow/providers/common/sql/hooks/sql.py", line 609, in _create_autocommit_connection
    with closing(self.get_conn()) as conn:
                 ^^^^^^^^^^^^^^^
  File "/home/airflow/.local/lib/python3.12/site-packages/airflow/providers/postgres/hooks/postgres.py", line 181, in get_conn
    self.conn = psycopg2.connect(**conn_args)
                ^^^^^^^^^^^^^^^^^^^^^^^^^^^^^
  File "/home/airflow/.local/lib/python3.12/site-packages/psycopg2/__init__.py", line 122, in connect
    conn = _connect(dsn, connection_factory=connection_factory, **kwasync)
           ^^^^^^^^^^^^^^^^^^^^^^^^^^^^^^^^^^^^^^^^^^^^^^^^^^^^^^^^^^^^^^^
psycopg2.OperationalError: connection to server at "172.21.0.7", port 5432 failed: FATAL:  database "articls" does not exist

[2024-11-08T13:37:56.485+0000] {logging_mixin.py:190} INFO - Task instance in failure state
[2024-11-08T13:37:56.485+0000] {logging_mixin.py:190} INFO - Task start:2024-11-08 13:37:55.617329+00:00 end:2024-11-08 13:37:56.484292+00:00 duration:0.866963
[2024-11-08T13:37:56.486+0000] {logging_mixin.py:190} INFO - Task:<Task(PostgresOperator): test_connection> dag:<DAG: create_postgres_table_dag> dagrun:<DagRun create_postgres_table_dag @ 2024-11-08 13:37:44.123879+00:00: manual__2024-11-08T13:37:44.123879+00:00, state:running, queued_at: 2024-11-08 13:37:44.148463+00:00. externally triggered: True>
[2024-11-08T13:37:56.486+0000] {logging_mixin.py:190} INFO - Failure caused by connection to server at "172.21.0.7", port 5432 failed: FATAL:  database "articls" does not exist
[2024-11-08T13:37:56.487+0000] {taskinstance.py:1225} INFO - Marking task as UP_FOR_RETRY. dag_id=create_postgres_table_dag, task_id=test_connection, run_id=manual__2024-11-08T13:37:44.123879+00:00, execution_date=20241108T133744, start_date=20241108T133755, end_date=20241108T133756
[2024-11-08T13:37:56.533+0000] {taskinstance.py:340} INFO - ::group::Post task execution logs
[2024-11-08T13:37:56.534+0000] {standard_task_runner.py:124} ERROR - Failed to execute job 8 for task test_connection (connection to server at "172.21.0.7", port 5432 failed: FATAL:  database "articls" does not exist
; 273)
Traceback (most recent call last):
  File "/home/airflow/.local/lib/python3.12/site-packages/airflow/task/task_runner/standard_task_runner.py", line 117, in _start_by_fork
    ret = args.func(args, dag=self.dag)
          ^^^^^^^^^^^^^^^^^^^^^^^^^^^^^
  File "/home/airflow/.local/lib/python3.12/site-packages/airflow/cli/cli_config.py", line 49, in command
    return func(*args, **kwargs)
           ^^^^^^^^^^^^^^^^^^^^^
  File "/home/airflow/.local/lib/python3.12/site-packages/airflow/utils/cli.py", line 116, in wrapper
    return f(*args, **kwargs)
           ^^^^^^^^^^^^^^^^^^
  File "/home/airflow/.local/lib/python3.12/site-packages/airflow/cli/commands/task_command.py", line 483, in task_run
    task_return_code = _run_task_by_selected_method(args, _dag, ti)
                       ^^^^^^^^^^^^^^^^^^^^^^^^^^^^^^^^^^^^^^^^^^^^
  File "/home/airflow/.local/lib/python3.12/site-packages/airflow/cli/commands/task_command.py", line 256, in _run_task_by_selected_method
    return _run_raw_task(args, ti)
           ^^^^^^^^^^^^^^^^^^^^^^^
  File "/home/airflow/.local/lib/python3.12/site-packages/airflow/cli/commands/task_command.py", line 341, in _run_raw_task
    return ti._run_raw_task(
           ^^^^^^^^^^^^^^^^^
  File "/home/airflow/.local/lib/python3.12/site-packages/airflow/utils/session.py", line 97, in wrapper
    return func(*args, session=session, **kwargs)
           ^^^^^^^^^^^^^^^^^^^^^^^^^^^^^^^^^^^^^^
  File "/home/airflow/.local/lib/python3.12/site-packages/airflow/models/taskinstance.py", line 3005, in _run_raw_task
    return _run_raw_task(
           ^^^^^^^^^^^^^^
  File "/home/airflow/.local/lib/python3.12/site-packages/airflow/models/taskinstance.py", line 273, in _run_raw_task
    TaskInstance._execute_task_with_callbacks(
  File "/home/airflow/.local/lib/python3.12/site-packages/airflow/models/taskinstance.py", line 3159, in _execute_task_with_callbacks
    result = self._execute_task(context, task_orig)
             ^^^^^^^^^^^^^^^^^^^^^^^^^^^^^^^^^^^^^^
  File "/home/airflow/.local/lib/python3.12/site-packages/airflow/models/taskinstance.py", line 3183, in _execute_task
    return _execute_task(self, context, task_orig)
           ^^^^^^^^^^^^^^^^^^^^^^^^^^^^^^^^^^^^^^^
  File "/home/airflow/.local/lib/python3.12/site-packages/airflow/models/taskinstance.py", line 767, in _execute_task
    result = _execute_callable(context=context, **execute_callable_kwargs)
             ^^^^^^^^^^^^^^^^^^^^^^^^^^^^^^^^^^^^^^^^^^^^^^^^^^^^^^^^^^^^^
  File "/home/airflow/.local/lib/python3.12/site-packages/airflow/models/taskinstance.py", line 733, in _execute_callable
    return ExecutionCallableRunner(
           ^^^^^^^^^^^^^^^^^^^^^^^^
  File "/home/airflow/.local/lib/python3.12/site-packages/airflow/utils/operator_helpers.py", line 252, in run
    return self.func(*args, **kwargs)
           ^^^^^^^^^^^^^^^^^^^^^^^^^^
  File "/home/airflow/.local/lib/python3.12/site-packages/airflow/models/baseoperator.py", line 417, in wrapper
    return func(self, *args, **kwargs)
           ^^^^^^^^^^^^^^^^^^^^^^^^^^^
  File "/home/airflow/.local/lib/python3.12/site-packages/airflow/providers/common/sql/operators/sql.py", line 284, in execute
    output = hook.run(
             ^^^^^^^^^
  File "/home/airflow/.local/lib/python3.12/site-packages/airflow/providers/common/sql/hooks/sql.py", line 485, in run
    with self._create_autocommit_connection(autocommit) as conn:
         ^^^^^^^^^^^^^^^^^^^^^^^^^^^^^^^^^^^^^^^^^^^^^^
  File "/usr/local/lib/python3.12/contextlib.py", line 137, in __enter__
    return next(self.gen)
           ^^^^^^^^^^^^^^
  File "/home/airflow/.local/lib/python3.12/site-packages/airflow/providers/common/sql/hooks/sql.py", line 609, in _create_autocommit_connection
    with closing(self.get_conn()) as conn:
                 ^^^^^^^^^^^^^^^
  File "/home/airflow/.local/lib/python3.12/site-packages/airflow/providers/postgres/hooks/postgres.py", line 181, in get_conn
    self.conn = psycopg2.connect(**conn_args)
                ^^^^^^^^^^^^^^^^^^^^^^^^^^^^^
  File "/home/airflow/.local/lib/python3.12/site-packages/psycopg2/__init__.py", line 122, in connect
    conn = _connect(dsn, connection_factory=connection_factory, **kwasync)
           ^^^^^^^^^^^^^^^^^^^^^^^^^^^^^^^^^^^^^^^^^^^^^^^^^^^^^^^^^^^^^^^
psycopg2.OperationalError: connection to server at "172.21.0.7", port 5432 failed: FATAL:  database "articls" does not exist

[2024-11-08T13:37:56.595+0000] {local_task_job_runner.py:266} INFO - Task exited with return code 1
[2024-11-08T13:37:56.681+0000] {taskinstance.py:3895} INFO - 0 downstream tasks scheduled from follow-on schedule check
[2024-11-08T13:37:56.686+0000] {local_task_job_runner.py:245} INFO - ::endgroup::
